Workbook

Sheet 24-25
F3: 45383 | M3: 45413 | T3: 45444 | AA3: 45474 | AH3: 45505 | AO3: 45536 | AV3: 45566 | BC3: 45597 | BJ3: 45627 | BQ3: 45658 | BX3: 45689 | CE3: 45717
A4: Category | B4: Product Description | C4: CIF Rate | D4: NPR CASE RATE | E4: Pack Size | F4: April-24 Opening | G4: PURCHASES OF APRIL | H4: PRIMARY TILL 31-04-2024 | I4: SALES RETURN | J4: CLOSING | K4: March Transit | L4: April Transit | M4: May-24 Opening | N4: PURCHASES OF May | O4: PRIMARY TILL 31-05-2024 | P4: SALES RETURN | Q4: CLOSING | R4: May Transit | S4: June PI Plan | T4: June-24 Opening | U4: PURCHASES OF June | V4: PRIMARY TILL 30-06-2024 | W4: SALES RETURN | X4: CLOSING | Y4: June Transit | Z4: July PI Plan | AA4: July-24 Opening | AB4: PURCHASES OF July | AC4: PRIMARY TILL 31-07-2024 | AD4: SALES RETURN | AE4: CLOSING | AF4: July Transit | AG4: Aug PI Plan | AH4: Aug-24 Opening | AI4: PURCHASES OF Aug | AJ4: PRIMARY TILL 31-08-2024 | AK4: SALES RETURN | AL4: CLOSING | AM4: Aug Transit | AN4: Sept PI Plan | AO4: Sept-24 Opening | AP4: PURCHASES OF Sept | AQ4: PRIMARY TILL 30-09-2024 | AR4: SALES RETURN | AS4: CLOSING | AT4: Sept Transit | AU4: Oct PI Plan | AV4: Oct-24 Opening | AW4: PURCHASES OF OCT | AX4: PRIMARY TILL 30-10-2024 | AY4: SALES RETURN | AZ4: CLOSING | BA4: Oct Transit | BB4: Sept PI Plan | BC4: Nov-24 Opening | BD4: PURCHASES OF Nov | BE4: PRIMARY TILL 30-11-2024 | BF4: SALES RETURN | BG4: CLOSING | BH4: Nov Transit | BI4: Dec PI Plan | BJ4: Dec-24 Opening | BK4: PURCHASES OF DEC | BL4: PRIMARY TILL 30-12-2024 | BM4: SALES RETURN | BN4: CLOSING | BO4: Dec Transit | BP4: Jan-025 PI Plan | BQ4: Jan-25 Opening | BR4: PURCHASES OF Jan | BS4: PRIMARY TILL 31-01-2025 | BT4: SALES RETURN | BU4: CLOSING | BV4: Jan Transit | BW4: Feb-025 PI Plan | BX4: Feb-25 Opening | BY4: PURCHASES OF FEB' | BZ4: PRIMARY TILL 28-02-2025 | CA4: SALES RETURN | CB4: CLOSING | CC4: Feb Transit | CD4: March-025 PI Plan | CE4: March-25 Opening | CF4: PURCHASES OF MARCH' | CG4: PRIMARY TILL 31-03-2025 | CH4: SALES RETURN | CI4: CLOSING
A5: BAKING POWDER | B5: WKFLD. BAKING POWDER 100*100GM | C5: 1204 | D5: 3885.101 | E5: 100 | F5: 5.65 | G5: 0 | H5: 3.27 | I5: 2.27 | J5: =F5+G5+I5-H5 -> 4.65 | L5: 100 | M5: =J5 -> 4.65 | N5: 100 | O5: 102.65 | P5: 6 | Q5: =M5+N5+P5-O5 -> 8 | R5: 100 | S5: 50 | T5: =Q5 -> 8 | U5: 100 | V5: 65 | X5: =T5+U5+W5-V5 -> 43 | AA5: =X5 -> 43 | AB5: 125 | AC5: 91.4 | AD5: 4.4 | AE5: =AA5+AB5+AD5-AC5 -> 81 | AH5: =AE5 -> 81 | AJ5: 88.69 | AK5: 7.69 | AL5: =AH5+AI5+AK5-AJ5 -> 0 | AM5: 50 | AN5: 100 | AO5: =AL5 -> 0 | AP5: 150 | AQ5: 81 | AS5: =AO5+AP5+AR5-AQ5 -> 69 | AV5: =AS5 -> 69 | AX5: 28 | AZ5: =AV5+AW5+AY5-AX5 -> 41 | BC5: =AZ5 -> 41 | BD5: 75 | BE5: 67 | BF5: 5 | BG5: =BC5+BD5+BF5-BE5 -> 54 | BJ5: =BG5 -> 54 | BK5: 50 | BL5: 41.4 | BM5: 14.1 | BN5: =BJ5+BK5+BM5-BL5 -> 76.7 | BQ5: =BN5 -> 76.7 | BS5: 77 | BT5: 4.92 | BU5: =BQ5+BR5+BT5-BS5 -> 4.62 | BV5: 25 | BX5: =BU5 -> 4.62 | BY5: 25 | BZ5: 34.36 | CA5: 4.74 | CB5: =BX5+BY5+CA5-BZ5 -> 0 | CE5: =CB5 -> 0 | CF5: 125 | CG5: 65 | CH5: 6.34 | CI5: =CE5+CF5+CH5-CG5 -> 66.34
A6: BAKING POWDER | B6: WKFLD. BAKING POWDER 30*400GM | C6: 1178 | D6: 3118.6869 | E6: 30 | F6: 265.8 | G6: 0 | H6: 171.1 | I6: 19.2 | J6: =F6+G6+I6-H6 -> 113.9 | L6: 330 | M6: =J6 -> 113.9 | N6: 330 | O6: 294.43 | P6: 10 | Q6: =M6+N6+P6-O6 -> 159.47 | R6: 250 | S6: 250 | T6: =Q6 -> 159.47 | U6: 250 | V6: 229 | W6: 2 | X6: =T6+U6+W6-V6 -> 182.47 | AA6: =X6 -> 182.47 | AB6: 350 | AC6: 214.6 | AD6: 9 | AE6: =AA6+AB6+AD6-AC6 -> 326.87 | AH6: =AE6 -> 326.87 | AJ6: 212.5333 | AK6: 6.73 | AL6: =AH6+AI6+AK6-AJ6 -> 121.0667 | AM6: 250 | AN6: 250 | AO6: =AL6 -> 121.0667 | AP6: 500 | AQ6: 363.1333 | AS6: =AO6+AP6+AR6-AQ6 -> 257.9334 | AV6: =AS6 -> 257.9334 | AX6: 86 | AZ6: =AV6+AW6+AY6-AX6 -> 171.9334 | BC6: =AZ6 -> 171.9334 | BD6: 200 | BE6: 285 | BF6: 0 | BG6: =BC6+BD6+BF6-BE6 -> 86.9334 | BH6: 250 | BJ6: =BG6 -> 86.9334 | BK6: 450 | BL6: 316.8 | BM6: 41.5667 | BN6: =BJ6+BK6+BM6-BL6 -> 261.7001 | BQ6: =BN6 -> 261.7001 | BS6: 268.03333 | BT6: 36.8 | BU6: =BQ6+BR6+BT6-BS6 -> 30.466767 | BV6: 450 | BX6: =BU6 -> 30.466767 | BY6: 390 | BZ6: 392 | CA6: 8.5333 | CB6: =BX6+BY6+CA6-BZ6 -> 37.000067 | CE6: =CB6 -> 37.000067 | CF6: 350.00003 | CG6: 349.2 | CH6: 12.0333 | CI6: =CE6+CF6+CH6-CG6 -> 49.8334
A7: BAKING POWDER | B7: WKFLD. BAKING POWDER 4*3KG | C7: 832 | D7: 2239.0572 | E7: 4 | F7: 240 | G7: 0 | H7: 108.5 | I7: 3 | J7: =F7+G7+I7-H7 -> 134.5 | L7: 100 | M7: =J7 -> 134.5 | N7: 100 | O7: 234.5 | P7: 0 | Q7: =M7+N7+P7-O7 -> 0 | R7: 100 | S7: 100 | T7: =Q7 -> 0 | U7: 100 | V7: 100 | X7: =T7+U7+W7-V7 -> 0 | AA7: =X7 -> 0 | AB7: 450 | AC7: 220.5 | AD7: 0 | AE7: =AA7+AB7+AD7-AC7 -> 229.5 | AH7: =AE7 -> 229.5 | AJ7: 220 | AK7: 0 | AL7: =AH7+AI7+AK7-AJ7 -> 9.5 | AM7: 250 | AN7: 300 | AO7: =AL7 -> 9.5 | AP7: 510 | AQ7: 216.5 | AS7: =AO7+AP7+AR7-AQ7 -> 303 | AV7: =AS7 -> 303 | AX7: 126 | AZ7: =AV7+AW7+AY7-AX7 -> 177 | BC7: =AZ7 -> 177 | BD7: 40 | BE7: 120 | BF7: 0 | BG7: =BC7+BD7+BF7-BE7 -> 97 | BH7: 200 | BJ7: =BG7 -> 97 | BK7: 350 | BL7: 238 | BM7: 58 | BN7: =BJ7+BK7+BM7-BL7 -> 267 | BQ7: =BN7 -> 267 | BS7: 225 | BT7: 22.5 | BU7: =BQ7+BR7+BT7-BS7 -> 64.5 | BV7: 100 | BX7: =BU7 -> 64.5 | BY7: 100 | BZ7: 115 | CA7: 8 | CB7: =BX7+BY7+CA7-BZ7 -> 57.5 | CE7: =CB7 -> 57.5 | CF7: 450 | CG7: 165.5 | CH7: 65.5 | CI7: =CE7+CF7+CH7-CG7 -> 407.5
B8: Baking Powder Total | F8: =SUM(F5:F7) -> 511.45 | G8: =SUM(G5:G7) -> 0 | H8: =SUM(H5:H7) -> 282.87 | I8: =SUM(I5:I7) -> 24.47 | J8: =SUM(J5:J7) -> 253.05 | K8: =SUM(K5:K7) -> 0 | L8: =SUM(L5:L7) -> 530 | M8: =SUM(M5:M7) -> 253.05 | ... CI8: =SUM(CI5:CI7) -> 523.6734
A9: BAKING SODA | B9: WKFLD. BAKING SODA 100*100GM | C9: 1160 | D9: 3885.0039 | E9: 100 | F9: 51.5 | G9: 0 | H9: 52.62 | I9: 1.22 | J9: =F9+G9+I9-H9 -> 0.1 | L9: 50 | M9: =J9 -> 0.1 | N9: 50 | O9: 60.1 | P9: 10 | Q9: =M9+N9+P9-O9 -> 0 | R9: 100 | S9: 50 | T9: =Q9 -> 0 | U9: 100 | V9: 56 | X9: =T9+U9+W9-V9 -> 44 | AA9: =X9 -> 44 | AB9: 100 | AC9: 82.27 | AD9: 4.27 | AE9: =AA9+AB9+AD9-AC9 -> 66 | AH9: =AE9 -> 66 | AJ9: 70.92 | AK9: 4.92 | AL9: =AH9+AI9+AK9-AJ9 -> 0 | AM9: 50 | AN9: 125 | AO9: =AL9 -> 0 | AP9: 175 | AQ9: 69.02 | AS9: =AO9+AP9+AR9-AQ9 -> 105.98 | AV9: =AS9 -> 105.98 | AX9: 26 | AZ9: =AV9+AW9+AY9-AX9 -> 79.98 | BC9: =AZ9 -> 79.98 | BD9: 25 | BE9: 73 | BF9: 0 | BG9: =BC9+BD9+BF9-BE9 -> 31.98 | BJ9: =BG9 -> 31.98 | BK9: 75 | BL9: 43.38 | BM9: 7.76 | BN9: =BJ9+BK9+BM9-BL9 -> 71.36 | BQ9: =BN9 -> 71.36 | BS9: 54.01 | BT9: 0 | BU9: =BQ9+BR9+BT9-BS9 -> 17.35 | BV9: 25 | BX9: =BU9 -> 17.35 | BY9: 25 | BZ9: 39 | CA9: 3.6 | CB9: =BX9+BY9+CA9-BZ9 -> 6.95 | CE9: =CB9 -> 6.95 | CF9: 110 | CG9: 56 | CH9: 3.87 | CI9: =CE9+CF9+CH9-CG9 -> 64.82
B10: Baking Soda Total | F10: =SUM(F9) -> 51.5 | G10: =SUM(G9) -> 0 | H10: =SUM(H9) -> 52.62 | I10: =SUM(I9) -> 1.22 | J10: =SUM(J9) -> 0.1 | K10: =SUM(K9) -> 0 | L10: =SUM(L9) -> 50 | M10: =SUM(M9) -> 0.1 | ... CI10: =SUM(CI9) -> 64.82
A11: COCOA POWDER | B11: WKFLD. COCOA POWDER 40*150GM | C11: 5700 | D11: 18648.019 | E11: 40 | F11: 0 | G11: 0 | H11: 0 | I11: 0 | J11: =F11+G11+I11-H11 -> 0 | M11: =J11 -> 0 | N11: 0 | O11: 0 | P11: 0 | Q11: =M11+N11+P11-O11 -> 0 | T11: =Q11 -> 0 | U11: 0 | V11: 0 | X11: =T11+U11+W11-V11 -> 0 | AA11: =X11 -> 0 | AC11: 0 | AD11: 0 | AE11: =AA11+AB11+AD11-AC11 -> 0 | AH11: =AE11 -> 0 | AJ11: 0.43 | AK11: 0.43 | AL11: =AH11+AI11+AK11-AJ11 -> 0 | AM11: 50 | AN11: 50 | AO11: =AL11 -> 0 | AP11: 100 | AQ11: 53.3 | AS11: =AO11+AP11+AR11-AQ11 -> 46.7 | AV11: =AS11 -> 46.7 | AX11: 11.1 | AZ11: =AV11+AW11+AY11-AX11 -> 35.6 | BC11: =AZ11 -> 35.6 | BD11: 0 | BE11: 21.6 | BF11: 0 | BG11: =BC11+BD11+BF11-BE11 -> 14 | BJ11: =BG11 -> 14 | BK11: 50 | BL11: 35.4 | BM11: 2.4 | BN11: =BJ11+BK11+BM11-BL11 -> 31 | BQ11: =BN11 -> 31 | BS11: 26 | BT11: 0 | BU11: =BQ11+BR11+BT11-BS11 -> 5 | BX11: =BU11 -> 5 | BY11: 0 | BZ11: 5 | CA11: 0 | CB11: =BX11+BY11+CA11-BZ11 -> 7.1054274e-15 | CE11: =CB11 -> 7.1054274e-15 | CF11: 40 | CG11: 26.675 | CH11: 7.075 | CI11: =CE11+CF11+CH11-CG11 -> 20.4
A12: COCOA POWDER | B12: WKFLD. COCOA POWDER 96*50GM | C12: 4800 | D12: 22377.622 | E12: 96 | F12: 0 | G12: 0 | H12: 0 | I12: 0 | J12: =F12+G12+I12-H12 -> 0 | M12: =J12 -> 0 | N12: 0 | O12: 22.92 | P12: 22.92 | Q12: =M12+N12+P12-O12 -> 0 | T12: =Q12 -> 0 | U12: 0 | V12: 0 | X12: =T12+U12+W12-V12 -> 0 | AA12: =X12 -> 0 | AC12: 0 | AD12: 0 | AE12: =AA12+AB12+AD12-AC12 -> 0 | AH12: =AE12 -> 0 | AJ12: 0 | AK12: 0 | AL12: =AH12+AI12+AK12-AJ12 -> 0 | AM12: 25 | AN12: 50 | AO12: =AL12 -> 0 | AP12: 75 | AQ12: 40.25 | AS12: =AO12+AP12+AR12-AQ12 -> 34.75 | AV12: =AS12 -> 34.75 | AX12: 1 | AZ12: =AV12+AW12+AY12-AX12 -> 33.75 | BC12: =AZ12 -> 33.75 | BD12: 0 | BE12: 19 | BF12: 0 | BG12: =BC12+BD12+BF12-BE12 -> 14.75 | BJ12: =BG12 -> 14.75 | BK12: 50 | BL12: 31.5 | BM12: 1.75 | BN12: =BJ12+BK12+BM12-BL12 -> 35 | BQ12: =BN12 -> 35 | BS12: 23 | BT12: 0 | BU12: =BQ12+BR12+BT12-BS12 -> 12 | BX12: =BU12 -> 12 | BY12: 0 | BZ12: 2 | CA12: 0 | CB12: =BX12+BY12+CA12-BZ12 -> 10 | CE12: =CB12 -> 10 | CF12: 40.000016 | CG12: 15.25 | CH12: 4.1354 | CI12: =CE12+CF12+CH12-CG12 -> 38.885416
B13: Cocoa Powder Total | F13: =SUM(F11:F12) -> 0 | G13: =SUM(G11:G12) -> 0 | H13: =SUM(H11:H12) -> 0 | I13: =SUM(I11:I12) -> 0 | J13: =SUM(J11:J12) -> 0 | K13: =SUM(K11:K12) -> 0 | L13: =SUM(L11:L12) -> 0 | M13: =SUM(M11:M12) -> 0 | ... CI13: =SUM(CI11:CI12) -> 59.285416
A14: CORNFLOUR | B14: WKFLD. CORNFLOUR 100*100GM | C14: 950 | D14: 3885.0039 | E14: 100 | F14: 74.38 | G14: 0 | H14: 42 | I14: 3.73 | J14: =F14+G14+I14-H14 -> 36.11 | M14: =J14 -> 36.11 | N14: 30 | O14: 35.38 | P14: 5 | Q14: =M14+N14+P14-O14 -> 35.73 | R14: 75 | S14: 100 | T14: =Q14 -> 35.73 | U14: 75 | V14: 29 | X14: =T14+U14+W14-V14 -> 81.73 | AA14: =X14 -> 81.73 | AB14: 50 | AC14: 36.82 | AD14: 3.41 | AE14: =AA14+AB14+AD14-AC14 -> 98.32 | AH14: =AE14 -> 98.32 | AJ14: 53.07 | AK14: 4.44 | AL14: =AH14+AI14+AK14-AJ14 -> 49.69 | AN14: 50 | AO14: =AL14 -> 49.69 | AP14: 50 | AQ14: 48 | AS14: =AO14+AP14+AR14-AQ14 -> 51.69 | AV14: =AS14 -> 51.69 | AX14: 14 | AZ14: =AV14+AW14+AY14-AX14 -> 37.69 | BC14: =AZ14 -> 37.69 | BD14: 0 | BE14: 32.69 | BF14: 0 | BG14: =BC14+BD14+BF14-BE14 -> 5 | BH14: 75 | BJ14: =BG14 -> 5 | BK14: 135 | BL14: 39.25 | BM14: 2.23 | BN14: =BJ14+BK14+BM14-BL14 -> 102.98 | BQ14: =BN14 -> 102.98 | BS14: 55 | BT14: 5.07 | BU14: =BQ14+BR14+BT14-BS14 -> 53.05 | BX14: =BU14 -> 53.05 | BY14: 0 | BZ14: 14 | CA14: 5.65 | CB14: =BX14+BY14+CA14-BZ14 -> 44.7 | CE14: =CB14 -> 44.7 | CF14: 60 | CG14: 36 | CH14: 3.62 | CI14: =CE14+CF14+CH14-CG14 -> 72.32
A15: CORNFLOUR | B15: WKFLD. CORNFLOUR 20*500GM | C15: 790 | D15: 2079.1246 | E15: 20 | F15: 262.2 | G15: 0 | H15: 85 | I15: 7.15 | J15: =F15+G15+I15-H15 -> 184.35 | M15: =J15 -> 184.35 | N15: 0 | O15: 71.4 | P15: 5 | Q15: =M15+N15+P15-O15 -> 117.95 | R15: 200 | S15: 150 | T15: =Q15 -> 117.95 | U15: 200 | V15: 54 | X15: =T15+U15+W15-V15 -> 263.95 | AA15: =X15 -> 263.95 | AB15: 100 | AC15: 42.5 | AD15: 5.4 | AE15: =AA15+AB15+AD15-AC15 -> 326.85 | AH15: =AE15 -> 326.85 | AJ15: 152 | AK15: 4 | AL15: =AH15+AI15+AK15-AJ15 -> 178.85 | AN15: 175 | AO15: =AL15 -> 178.85 | AP15: 175 | AQ15: 155 | AS15: =AO15+AP15+AR15-AQ15 -> 198.85 | AV15: =AS15 -> 198.85 | AX15: 21 | AZ15: =AV15+AW15+AY15-AX15 -> 177.85 | BC15: =AZ15 -> 177.85 | BD15: 0 | BE15: 138 | BF15: 0 | BG15: =BC15+BD15+BF15-BE15 -> 39.85 | BH15: 50 | BJ15: =BG15 -> 39.85 | BK15: 110 | BL15: 131.1 | BM15: 11.35 | BN15: =BJ15+BK15+BM15-BL15 -> 30.1 | BQ15: =BN15 -> 30.1 | BS15: 39.55 | BT15: 9.45 | BU15: =BQ15+BR15+BT15-BS15 -> -8.5265128e-14 | BV15: 200 | BX15: =BU15 -> -8.5265128e-14 | BY15: 90 | BZ15: 83 | CA15: 2.15 | CB15: =BX15+BY15+CA15-BZ15 -> 9.15 | CC15: 100 | CE15: =CB15 -> 9.15 | CF15: 100 | CG15: 111.05 | CH15: 2.55 | CI15: =CE15+CF15+CH15-CG15 -> 0.65
A16: CORNFLOUR | B16: WKFLD. CORNFLOUR 25*1000GM | C16: 1516 | D16: 3885.0039 | E16: 25 | F16: 5.36 | G16: 0 | H16: 0.92 | I16: 0 | J16: =F16+G16+I16-H16 -> 4.44 | K16: 100 | M16: =J16 -> 4.44 | N16: 168 | O16: 92.44 | P16: 0 | Q16: =M16+N16+P16-O16 -> 80 | R16: 32 | S16: 150 | T16: =Q16 -> 80 | U16: 30 | V16: 49 | X16: =T16+U16+W16-V16 -> 61 | AA16: =X16 -> 61 | AB16: 100 | AC16: 33.08 | AD16: 5 | AE16: =AA16+AB16+AD16-AC16 -> 132.92 | AH16: =AE16 -> 132.92 | AJ16: 47.48 | AK16: 2.2 | AL16: =AH16+AI16+AK16-AJ16 -> 87.64 | AN16: 75 | AO16: =AL16 -> 87.64 | AP16: 75 | AQ16: 64 | AS16: =AO16+AP16+AR16-AQ16 -> 98.64 | AV16: =AS16 -> 98.64 | AX16: 16 | AZ16: =AV16+AW16+AY16-AX16 -> 82.64 | BC16: =AZ16 -> 82.64 | BD16: 71 | BE16: 29 | BF16: 0 | BG16: =BC16+BD16+BF16-BE16 -> 124.64 | BJ16: =BG16 -> 124.64 | BK16: 50 | BL16: 41.64 | BM16: 18.48 | BN16: =BJ16+BK16+BM16-BL16 -> 151.48 | BQ16: =BN16 -> 151.48 | BS16: 34 | BT16: 0 | BU16: =BQ16+BR16+BT16-BS16 -> 117.48 | BX16: =BU16 -> 117.48 | BY16: 0 | BZ16: 4 | CA16: 0 | CB16: =BX16+BY16+CA16-BZ16 -> 113.48 | CE16: =CB16 -> 113.48 | CF16: 20 | CG16: 71 | CH16: 1.64 | CI16: =CE16+CF16+CH16-CG16 -> 64.12
B17: Corn Flour Total | F17: =SUM(F14:F16) -> 341.94 | G17: =SUM(G14:G16) -> 0 | H17: =SUM(H14:H16) -> 127.92 | I17: =SUM(I14:I16) -> 10.88 | J17: =SUM(J14:J16) -> 224.9 | K17: =SUM(K14:K16) -> 100 | L17: =SUM(L14:L16) -> 0 | M17: =SUM(M14:M16) -> 224.9 | ... CI17: =SUM(CI14:CI16) -> 137.09
A18: CUSTARD POWDER | B18: WKFLD. CUSTARD POWDER VANILLA 100*100GM | C18: 1538 | D18: 5283.6053 | E18: 100 | F18: 28.58 | G18: 0 | H18: 23 | I18: 0 | J18: =F18+G18+I18-H18 -> 5.58 | L18: 50 | M18: =J18 -> 5.58 | N18: 50 | O18: 60.58 | P18: 5 | Q18: =M18+N18+P18-O18 -> 0 | R18: 50 | S18: 50 | T18: =Q18 -> 0 | U18: 50 | V18: 50 | X18: =T18+U18+W18-V18 -> 0 | AA18: =X18 -> 0 | AB18: 150 | AC18: 32.91 | AD18: 2.91 | AE18: =AA18+AB18+AD18-AC18 -> 120 | AH18: =AE18 -> 120 | AJ18: 43.83 | AK18: 2.05 | AL18: =AH18+AI18+AK18-AJ18 -> 78.22 | AN18: 75 | AO18: =AL18 -> 78.22 | AP18: 75 | AQ18: 41 | AS18: =AO18+AP18+AR18-AQ18 -> 112.22 | AV18: =AS18 -> 112.22 | AX18: 1 | AZ18: =AV18+AW18+AY18-AX18 -> 111.22 | BC18: =AZ18 -> 111.22 | BD18: 0 | BE18: 14 | BF18: 0 | BG18: =BC18+BD18+BF18-BE18 -> 97.22 | BJ18: =BG18 -> 97.22 | BK18: 0 | BL18: 12.84 | BM18: 17.84 | BN18: =BJ18+BK18+BM18-BL18 -> 102.22 | BQ18: =BN18 -> 102.22 | BS18: 27 | BT18: 3.29 | BU18: =BQ18+BR18+BT18-BS18 -> 78.51 | BX18: =BU18 -> 78.51 | BY18: 0 | BZ18: 7 | CA18: 6.02 | CB18: =BX18+BY18+CA18-BZ18 -> 77.53 | CE18: =CB18 -> 77.53 | CF18: 25 | CG18: 33 | CH18: 3.45 | CI18: =CE18+CF18+CH18-CG18 -> 72.98
A19: CUSTARD POWDER | B19: WKFLD. CUSTARD POWDER VANILLA 20*500GM | C19: 1248 | D19: 3758.4175 | E19: 20 | F19: 84.55 | G19: 0 | H19: 68 | I19: 7.4 | J19: =F19+G19+I19-H19 -> 23.95 | L19: 50 | M19: =J19 -> 23.95 | N19: 50 | O19: 78.95 | P19: 5 | Q19: =M19+N19+P19-O19 -> 0 | R19: 100 | S19: 125 | T19: =Q19 -> 0 | U19: 100 | V19: 51 | X19: =T19+U19+W19-V19 -> 49 | AA19: =X19 -> 49 | AB19: 200 | AC19: 44.85 | AD19: 7 | AE19: =AA19+AB19+AD19-AC19 -> 211.15 | AH19: =AE19 -> 211.15 | AJ19: 77.05 | AK19: 0.05 | AL19: =AH19+AI19+AK19-AJ19 -> 134.15 | AN19: 100 | AO19: =AL19 -> 134.15 | AP19: 100 | AQ19: 63 | AS19: =AO19+AP19+AR19-AQ19 -> 171.15 | AV19: =AS19 -> 171.15 | AX19: 26 | AZ19: =AV19+AW19+AY19-AX19 -> 145.15 | BC19: =AZ19 -> 145.15 | BD19: 0 | BE19: 70 | BF19: 0 | BG19: =BC19+BD19+BF19-BE19 -> 75.15 | BJ19: =BG19 -> 75.15 | BK19: 0 | BL19: 65.4 | BM19: 25.75 | BN19: =BJ19+BK19+BM19-BL19 -> 35.5 | BO19: 25 | BQ19: =BN19 -> 35.5 | BS19: 36.55 | BT19: 1.05 | BU19: =BQ19+BR19+BT19-BS19 -> 0 | BV19: 75 | BX19: =BU19 -> 0 | BY19: 75 | BZ19: 36 | CA19: 7.55 | CB19: =BX19+BY19+CA19-BZ19 -> 46.55 | CE19: =CB19 -> 46.55 | CF19: 100 | CG19: 68 | CH19: 7.15 | CI19: =CE19+CF19+CH19-CG19 -> 85.7
B20: Custard Powder Total | F20: =SUM(F18:F19) -> 113.13 | G20: =SUM(G18:G19) -> 0 | H20: =SUM(H18:H19) -> 91 | I20: =SUM(I18:I19) -> 7.4 | J20: =SUM(J18:J19) -> 29.53 | K20: =SUM(K18:K19) -> 0 | L20: =SUM(L18:L19) -> 100 | M20: =SUM(M18:M19) -> 29.53 | ... CI20: =SUM(CI18:CI19) -> 158.68
A21: DRINKING CHOCOLATE | B21: WKFLD. DRINKING CHOCOLATE 20*500GM | C21: 2577 | D21: 10101.01 | E21: 20 | F21: 69 | G21: 199 | H21: 247.2 | I21: 0.75 | J21: =F21+G21+I21-H21 -> 21.55 | M21: =J21 -> 21.55 | N21: 150 | O21: 181.55 | P21: 10 | Q21: =M21+N21+P21-O21 -> 0 | R21: 150 | S21: 200 | T21: =Q21 -> 0 | U21: 0 | V21: 0 | X21: =T21+U21+W21-V21 -> 0 | AA21: =X21 -> 0 | AB21: 650 | AC21: 167.35 | AD21: 0.25 | AE21: =AA21+AB21+AD21-AC21 -> 482.9 | AH21: =AE21 -> 482.9 | AJ21: 114.55 | AK21: 5.55 | AL21: =AH21+AI21+AK21-AJ21 -> 373.9 | AO21: =AL21 -> 373.9 | AP21: 0 | AQ21: 170 | AS21: =AO21+AP21+AR21-AQ21 -> 203.9 | AV21: =AS21 -> 203.9 | AX21: 50 | AZ21: =AV21+AW21+AY21-AX21 -> 153.9 | BC21: =AZ21 -> 153.9 | BD21: 250 | BE21: 333.1 | BF21: 0 | BG21: =BC21+BD21+BF21-BE21 -> 70.8 | BH21: 250 | BJ21: =BG21 -> 70.8 | BK21: 189 | BL21: 147.5 | BM21: 22.05 | BN21: =BJ21+BK21+BM21-BL21 -> 134.35 | BO21: 500 | BQ21: =BN21 -> 134.35 | BS21: 97.75 | BT21: 13.45 | BU21: =BQ21+BR21+BT21-BS21 -> 50.05 | BV21: 500 | BX21: =BU21 -> 50.05 | BY21: 0 | BZ21: 54.05 | CA21: 4 | CB21: =BX21+BY21+CA21-BZ21 -> 0 | CE21: =CB21 -> 0 | CF21: 536 | CG21: 532.45 | CH21: 4.15 | CI21: =CE21+CF21+CH21-CG21 -> 7.7
A22: DRINKING CHOCOLATE | B22: WKFLD. DRINKING CHOCOLATE 20*500GM+100GM | C22: 2577 | D22: 10101.01 | E22: 20 | BE22: 0 | BL22: 0 | BS22: 0 | BT22: 0 | BZ22: 0 | CE22: =CB22 -> 0 | CF22: 496 | CG22: 9 | CH22: 0 | CI22: =CE22+CF22+CH22-CG22 -> 487
A23: DRINKING CHOCOLATE | B23: WKFLD. DRINKING CHOCOLATE 40*200GM | C23: 2469 | D23: 10878.011 | E23: 40 | F23: 33.475 | G23: 0 | H23: 21 | I23: 0.68 | J23: =F23+G23+I23-H23 -> 13.155 | L23: 20 | M23: =J23 -> 13.155 | N23: 20 | O23: 26.31 | P23: 0 | Q23: =M23+N23+P23-O23 -> 6.845 | R23: 25 | T23: =Q23 -> 6.845 | U23: 25 | V23: 4 | X23: =T23+U23+W23-V23 -> 27.845 | AA23: =X23 -> 27.845 | AB23: 20 | AC23: 27.015 | AD23: 1.45 | AE23: =AA23+AB23+AD23-AC23 -> 22.28 | AH23: =AE23 -> 22.28 | AJ23: 24.3 | AK23: 2.5 | AL23: =AH23+AI23+AK23-AJ23 -> 0.48 | AN23: 25 | AO23: =AL23 -> 0.48 | AP23: 25 | AQ23: 26.3 | AR23: 3 | AS23: =AO23+AP23+AR23-AQ23 -> 2.18 | AV23: =AS23 -> 2.18 | AX23: 2 | AZ23: =AV23+AW23+AY23-AX23 -> 0.18 | BC23: =AZ23 -> 0.18 | BD23: 25 | BE23: 23 | BF23: 9 | BG23: =BC23+BD23+BF23-BE23 -> 11.18 | BH23: 10 | BJ23: =BG23 -> 11.18 | BK23: 35 | BL23: 27.5 | BM23: 1.875 | BN23: =BJ23+BK23+BM23-BL23 -> 20.555 | BQ23: =BN23 -> 20.555 | BS23: 26.9 | BT23: 6.9 | BU23: =BQ23+BR23+BT23-BS23 -> 0.555 | BX23: =BU23 -> 0.555 | BY23: 0 | BZ23: 1 | CA23: 8.275 | CB23: =BX23+BY23+CA23-BZ23 -> 7.83 | CE23: =CB23 -> 7.83 | CF23: 50 | CG23: 16.325 | CH23: 1.975 | CI23: =CE23+CF23+CH23-CG23 -> 43.48
A24: DRINKING CHOCOLATE | B24: WKFLD. DRINKING CHOCOLATE 96*100GM | C24: 3340 | D24: 18648.019 | E24: 96 | F24: 140.41667 | G24: 0 | H24: 28.42 | I24: 0 | J24: =F24+G24+I24-H24 -> 111.99667 | M24: =J24 -> 111.99667 | N24: 0 | O24: 45.84 | P24: 5 | Q24: =M24+N24+P24-O24 -> 71.156666 | T24: =Q24 -> 71.156666 | U24: 0 | V24: 10 | X24: =T24+U24+W24-V24 -> 61.156666 | AA24: =X24 -> 61.156666 | AC24: 18.22 | AD24: 11.64 | AE24: =AA24+AB24+AD24-AC24 -> 54.576666 | AH24: =AE24 -> 54.576666 | AJ24: 5.77 | AK24: 2.77 | AL24: =AH24+AI24+AK24-AJ24 -> 51.576666 | AN24: 25 | AO24: =AL24 -> 51.576666 | AP24: 25 | AQ24: 32.625 | AR24: 2 | AS24: =AO24+AP24+AR24-AQ24 -> 45.951666 | AV24: =AS24 -> 45.951666 | AX24: 5 | AZ24: =AV24+AW24+AY24-AX24 -> 40.951666 | BC24: =AZ24 -> 40.951666 | BD24: 0 | BE24: 31.708333 | BF24: 9 | BG24: =BC24+BD24+BF24-BE24 -> 18.243333 | BH24: 10 | BJ24: =BG24 -> 18.243333 | BK24: 20 | BL24: 11.052083 | BM24: 1.1459 | BN24: =BJ24+BK24+BM24-BL24 -> 28.33715 | BQ24: =BN24 -> 28.33715 | BS24: 24.489583 | BT24: 1.895833 | BU24: =BQ24+BR24+BT24-BS24 -> 5.7434 | BX24: =BU24 -> 5.7434 | BY24: 0 | BZ24: 1 | CA24: 3.0104 | CB24: =BX24+BY24+CA24-BZ24 -> 7.7538 | CE24: =CB24 -> 7.7538 | CF24: 34.999983 | CG24: =20.6875-3 -> 17.6875 | CH24: 5.6771 | CI24: =CE24+CF24+CH24-CG24 -> 30.743383
B25: Drinking Chocolate Total | F25: =SUM(F21:F24) -> 242.89167 | G25: =SUM(G21:G24) -> 199 | H25: =SUM(H21:H24) -> 296.62 | I25: =SUM(I21:I24) -> 1.43 | J25: =SUM(J21:J24) -> 146.70167 | K25: =SUM(K21:K24) -> 0 | L25: =SUM(L21:L24) -> 20 | M25: =SUM(M21:M24) -> 146.70167 | ... CI25: =SUM(CI21:CI24) -> 568.92338
A26: JELLY CRYSTALS | B26: WKFLD. JELLY CRYSTALS MANGO 100*90GM | C26: 1928 | D26: 6993.007 | E26: 100 | F26: 17.06 | G26: 0 | H26: 0 | I26: 0 | J26: =F26+G26+I26-H26 -> 17.06 | M26: =J26 -> 17.06 | N26: 0 | O26: =VLOOKUP(B26,[1]Sheet1!$A:$B,2,0) -> 17.06 | P26: 0 | Q26: =M26+N26+P26-O26 -> 0 | T26: =Q26 -> 0 | U26: 0 | V26: 0 | X26: =T26+U26+W26-V26 -> 0 | AA26: =X26 -> 0 | AC26: 0 | AD26: 0 | AE26: =AA26+AB26+AD26-AC26 -> 0 | AH26: =AE26 -> 0 | AJ26: 0 | AK26: 0 | AL26: =AH26+AI26+AK26-AJ26 -> 0 | AM26: 15 | AO26: =AL26 -> 0 | AP26: 0 | AQ26: 0 | AS26: =AO26+AP26+AR26-AQ26 -> 0 | AV26: =AS26 -> 0 | AX26: 0 | AZ26: =AV26+AW26+AY26-AX26 -> 0 | BC26: =AZ26 -> 0 | BD26: 0 | BE26: 0 | BF26: 0 | BG26: =BC26+BD26+BF26-BE26 -> 0 | BJ26: =BG26 -> 0 | BK26: 0 | BL26: 0 | BM26: 0 | BN26: =BJ26+BK26+BM26-BL26 -> 0 | BQ26: =BN26 -> 0 | BS26: 0 | BT26: 0 | BU26: =BQ26+BR26+BT26-BS26 -> 0 | BX26: =BU26 -> 0 | BY26: 0 | BZ26: 0 | CA26: 0 | CB26: =BX26+BY26+CA26-BZ26 -> 0 | CE26: =CB26 -> 0 | CF26: 0 | CG26: 0 | CH26: 0 | CI26: =CE26+CF26+CH26-CG26 -> 0
A27: JELLY CRYSTALS | B27: WKFLD. JELLY CRYSTALS PINEAPPLE 100*90GM | C27: 1928 | D27: 6993.007 | E27: 100 | F27: 24.05 | G27: 0 | H27: 0 | I27: 0 | J27: =F27+G27+I27-H27 -> 24.05 | M27: =J27 -> 24.05 | N27: 0 | O27: =VLOOKUP(B27,[1]Sheet1!$A:$B,2,0) -> 0.36 | P27: 0 | Q27: =M27+N27+P27-O27 -> 23.69 | T27: =Q27 -> 23.69 | U27: 0 | V27: 0 | X27: =T27+U27+W27-V27 -> 23.69 | AA27: =X27 -> 23.69 | AC27: 0 | AD27: 0 | AE27: =AA27+AB27+AD27-AC27 -> 23.69 | AH27: =AE27 -> 23.69 | AJ27: 0 | AK27: 0 | AL27: =AH27+AI27+AK27-AJ27 -> 23.69 | AO27: =AL27 -> 23.69 | AP27: 0 | AQ27: 0 | AS27: =AO27+AP27+AR27-AQ27 -> 23.69 | AV27: =AS27 -> 23.69 | AX27: 0 | AZ27: =AV27+AW27+AY27-AX27 -> 23.69 | BC27: =AZ27 -> 23.69 | BD27: 0 | BE27: 0 | BF27: 0 | BG27: =BC27+BD27+BF27-BE27 -> 23.69 | BJ27: =BG27 -> 23.69 | BK27: 0 | BL27: 0 | BM27: 0 | BN27: =BJ27+BK27+BM27-BL27 -> 23.69 | BQ27: =BN27 -> 23.69 | BS27: 0 | BT27: 0 | BU27: =BQ27+BR27+BT27-BS27 -> 23.69 | BX27: =BU27 -> 23.69 | BY27: 0 | BZ27: 0 | CA27: 0 | CB27: =BX27+BY27+CA27-BZ27 -> 23.69 | CE27: =CB27 -> 23.69 | CF27: 0 | CG27: 0 | CH27: 0 | CI27: =CE27+CF27+CH27-CG27 -> 23.69
A28: JELLY CRYSTALS | B28: WKFLD. JELLY CRYSTALS ORANGE 100*90GM | C28: 1928 | D28: 6993.007 | E28: 100 | F28: 21.89 | G28: 0 | H28: 0 | I28: 0 | J28: =F28+G28+I28-H28 -> 21.89 | M28: =J28 -> 21.89 | N28: 0 | O28: =VLOOKUP(B28,[1]Sheet1!$A:$B,2,0) -> 21.89 | P28: 0 | Q28: =M28+N28+P28-O28 -> 0 | T28: =Q28 -> 0 | U28: 0 | V28: 0 | X28: =T28+U28+W28-V28 -> 0 | AA28: =X28 -> 0 | AC28: 0 | AD28: 0 | AE28: =AA28+AB28+AD28-AC28 -> 0 | AH28: =AE28 -> 0 | AJ28: 0 | AK28: 0 | AL28: =AH28+AI28+AK28-AJ28 -> 0 | AO28: =AL28 -> 0 | AP28: 0 | AQ28: 0 | AS28: =AO28+AP28+AR28-AQ28 -> 0 | AV28: =AS28 -> 0 | AX28: 0 | AZ28: =AV28+AW28+AY28-AX28 -> 0 | BC28: =AZ28 -> 0 | BD28: 0 | BE28: 0 | BF28: 0 | BG28: =BC28+BD28+BF28-BE28 -> 0 | BJ28: =BG28 -> 0 | BK28: 0 | BL28: 0 | BM28: 0 | BN28: =BJ28+BK28+BM28-BL28 -> 0 | BQ28: =BN28 -> 0 | BS28: 0 | BT28: 0 | BU28: =BQ28+BR28+BT28-BS28 -> 0 | BX28: =BU28 -> 0 | BY28: 0 | BZ28: 0 | CA28: 0 | CB28: =BX28+BY28+CA28-BZ28 -> 0 | CE28: =CB28 -> 0 | CF28: 0 | CG28: 0 | CH28: 0 | CI28: =CE28+CF28+CH28-CG28 -> 0
A29: JELLY CRYSTALS | B29: WKFLD. JELLY CRYSTALS RASPBERRY 100*90GM | C29: 1928 | D29: 6993.007 | E29: 100 | F29: 19.8 | G29: 0 | H29: 0 | I29: 0 | J29: =F29+G29+I29-H29 -> 19.8 | M29: =J29 -> 19.8 | N29: 0 | O29: 19.8 | P29: 0 | Q29: =M29+N29+P29-O29 -> 0 | T29: =Q29 -> 0 | U29: 0 | V29: 0 | X29: =T29+U29+W29-V29 -> 0 | AA29: =X29 -> 0 | AB29: 15 | AC29: 15 | AD29: 0 | AE29: =AA29+AB29+AD29-AC29 -> 0 | AH29: =AE29 -> 0 | AJ29: 0 | AK29: 0 | AL29: =AH29+AI29+AK29-AJ29 -> 0 | AM29: 15 | AN29: 15 | AO29: =AL29 -> 0 | AP29: 30 | AQ29: 2 | AS29: =AO29+AP29+AR29-AQ29 -> 28 | AV29: =AS29 -> 28 | AX29: 0 | AZ29: =AV29+AW29+AY29-AX29 -> 28 | BC29: =AZ29 -> 28 | BD29: 0 | BE29: 0 | BF29: 0 | BG29: =BC29+BD29+BF29-BE29 -> 28 | BJ29: =BG29 -> 28 | BK29: 0 | BL29: 1 | BM29: 0 | BN29: =BJ29+BK29+BM29-BL29 -> 27 | BQ29: =BN29 -> 27 | BS29: 3 | BT29: 0 | BU29: =BQ29+BR29+BT29-BS29 -> 24 | BX29: =BU29 -> 24 | BY29: 0 | BZ29: 2 | CA29: 0 | CB29: =BX29+BY29+CA29-BZ29 -> 22 | CE29: =CB29 -> 22 | CF29: 0 | CG29: 3 | CH29: 0 | CI29: =CE29+CF29+CH29-CG29 -> 19
A30: JELLY CRYSTALS | B30: WKFLD. JELLY CRYSTALS STRAWBERRY 100*90GM | C30: 1928 | D30: 6993.007 | E30: 100 | F30: 11.14 | G30: 0 | H30: 0 | I30: 0 | J30: =F30+G30+I30-H30 -> 11.14 | M30: =J30 -> 11.14 | N30: 0 | O30: 10.43 | P30: 0 | Q30: =M30+N30+P30-O30 -> 0.71 | T30: =Q30 -> 0.71 | U30: 0 | V30: 0 | X30: =T30+U30+W30-V30 -> 0.71 | AA30: =X30 -> 0.71 | AB30: 15 | AC30: 15 | AD30: 0 | AE30: =AA30+AB30+AD30-AC30 -> 0.71 | AH30: =AE30 -> 0.71 | AJ30: 0 | AK30: 0 | AL30: =AH30+AI30+AK30-AJ30 -> 0.71 | AM30: 15 | AN30: 15 | AO30: =AL30 -> 0.71 | AP30: 30 | AQ30: 4 | AS30: =AO30+AP30+AR30-AQ30 -> 26.71 | AV30: =AS30 -> 26.71 | AX30: 0 | AZ30: =AV30+AW30+AY30-AX30 -> 26.71 | BC30: =AZ30 -> 26.71 | BD30: 0 | BE30: 1 | BF30: 1 | BG30: =BC30+BD30+BF30-BE30 -> 26.71 | BJ30: =BG30 -> 26.71 | BK30: 0 | BL30: 2 | BM30: 0 | BN30: =BJ30+BK30+BM30-BL30 -> 24.71 | BQ30: =BN30 -> 24.71 | BS30: 3 | BT30: 0 | BU30: =BQ30+BR30+BT30-BS30 -> 21.71 | BX30: =BU30 -> 21.71 | BY30: 0 | BZ30: 2 | CA30: 0 | CB30: =BX30+BY30+CA30-BZ30 -> 19.71 | CE30: =CB30 -> 19.71 | CF30: 0 | CG30: 3 | CH30: 0 | CI30: =CE30+CF30+CH30-CG30 -> 16.71
B31: Jelly Crystals Total | F31: =SUM(F26:F30) -> 93.94 | G31: =SUM(G26:G30) -> 0 | H31: =SUM(H26:H30) -> 0 | I31: =SUM(I26:I30) -> 0 | J31: =SUM(J26:J30) -> 93.94 | K31: =SUM(K26:K30) -> 0 | L31: =SUM(L26:L30) -> 0 | M31: =SUM(M26:M30) -> 93.94 | ... CI31: =SUM(CI26:CI30) -> 59.4
A32: MUSTARD POWDER | B32: WKFLD. MUSTARD POWDER 20*500GM | C32: 2454 | D32: 7614.6076 | E32: 20 | F32: 60.1 | G32: 0 | H32: 10 | I32: 3.25 | J32: =F32+G32+I32-H32 -> 53.35 | M32: =J32 -> 53.35 | N32: 0 | O32: =VLOOKUP(B32,[1]Sheet1!$A:$B,2,0) -> 22.9 | P32: 0 | Q32: =M32+N32+P32-O32 -> 30.45 | T32: =Q32 -> 30.45 | U32: 0 | V32: 9 | X32: =T32+U32+W32-V32 -> 21.45 | AA32: =X32 -> 21.45 | AC32: 17 | AD32: 2 | AE32: =AA32+AB32+AD32-AC32 -> 6.45 | AH32: =AE32 -> 6.45 | AJ32: 21.45 | AK32: 19 | AL32: =AH32+AI32+AK32-AJ32 -> 4 | AN32: 25 | AO32: =AL32 -> 4 | AP32: 25 | AQ32: 21 | AS32: =AO32+AP32+AR32-AQ32 -> 8 | AV32: =AS32 -> 8 | AX32: 3 | AZ32: =AV32+AW32+AY32-AX32 -> 5 | BC32: =AZ32 -> 5 | BD32: 25 | BE32: 17 | BF32: 9 | BG32: =BC32+BD32+BF32-BE32 -> 22 | BH32: 20 | BJ32: =BG32 -> 22 | BK32: 20 | BL32: 8.95 | BM32: 3.95 | BN32: =BJ32+BK32+BM32-BL32 -> 37 | BQ32: =BN32 -> 37 | BS32: 5 | BT32: 0 | BU32: =BQ32+BR32+BT32-BS32 -> 32 | BX32: =BU32 -> 32 | BY32: 0 | BZ32: 3 | CA32: 0 | CB32: =BX32+BY32+CA32-BZ32 -> 29 | CE32: =CB32 -> 29 | CF32: 0 | CG32: 2 | CH32: 11.4 | CI32: =CE32+CF32+CH32-CG32 -> 38.4
A33: MUSTARD POWDER | B33: WKFLD. MUSTARD POWDER 50*100GM | C33: 1618 | D33: 5439.0054 | E33: 50 | F33: 96.64 | G33: 0 | H33: 2 | I33: 0.46 | J33: =F33+G33+I33-H33 -> 95.1 | M33: =J33 -> 95.1 | N33: 0 | O33: =VLOOKUP(B33,[1]Sheet1!$A:$B,2,0) -> 19.08 | P33: 0 | Q33: =M33+N33+P33-O33 -> 76.02 | T33: =Q33 -> 76.02 | U33: 0 | V33: 7 | X33: =T33+U33+W33-V33 -> 69.02 | AA33: =X33 -> 69.02 | AC33: 13 | AD33: 1 | AE33: =AA33+AB33+AD33-AC33 -> 57.02 | AH33: =AE33 -> 57.02 | AJ33: 7 | AK33: 6.56 | AL33: =AH33+AI33+AK33-AJ33 -> 56.58 | AO33: =AL33 -> 56.58 | AP33: 0 | AQ33: 2 | AS33: =AO33+AP33+AR33-AQ33 -> 54.58 | AV33: =AS33 -> 54.58 | AX33: 0 | AZ33: =AV33+AW33+AY33-AX33 -> 54.58 | BC33: =AZ33 -> 54.58 | BD33: 0 | BE33: 0 | BF33: 0 | BG33: =BC33+BD33+BF33-BE33 -> 54.58 | BH33: 10 | BJ33: =BG33 -> 54.58 | BK33: 10 | BL33: 2.5 | BM33: 2.26 | BN33: =BJ33+BK33+BM33-BL33 -> 64.34 | BQ33: =BN33 -> 64.34 | BS33: 6 | BT33: 0 | BU33: =BQ33+BR33+BT33-BS33 -> 58.34 | BX33: =BU33 -> 58.34 | BY33: 0 | BZ33: 1 | CA33: 0 | CB33: =BX33+BY33+CA33-BZ33 -> 57.34 | CE33: =CB33 -> 57.34 | CF33: 0 | CG33: 1 | CH33: 4.74 | CI33: =CE33+CF33+CH33-CG33 -> 61.08
B34: Mustard Powder Total | F34: =SUM(F32:F33) -> 156.74 | G34: =SUM(G32:G33) -> 0 | H34: =SUM(H32:H33) -> 12 | I34: =SUM(I32:I33) -> 3.71 | J34: =SUM(J32:J33) -> 148.45 | K34: =SUM(K32:K33) -> 0 | L34: =SUM(L32:L33) -> 0 | M34: =SUM(M32:M33) -> 148.45 | ... CI34: =SUM(CI32:CI33) -> 99.48
A35: SAUCE | B35: WKFLD. MUSTARD SAUCE 24*225GM | C35: 1320 | D35: 4755.2448 | E35: 24 | F35: 3.791666 | G35: 0 | H35: 0 | I35: 0 | J35: =F35+G35+I35-H35 -> 3.791666 | M35: =J35 -> 3.791666 | N35: 0 | O35: 3 | P35: 5 | Q35: =M35+N35+P35-O35 -> 5.791666 | T35: =Q35 -> 5.791666 | U35: 0 | V35: 2 | X35: =T35+U35+W35-V35 -> 3.791666 | AA35: =X35 -> 3.791666 | AC35: 4.79 | AD35: 1 | AE35: =AA35+AB35+AD35-AC35 -> 0.001666 | AH35: =AE35 -> 0.001666 | AJ35: 0 | AK35: 0 | AL35: =AH35+AI35+AK35-AJ35 -> 0.001666 | AN35: 10 | AO35: =AL35 -> 0.001666 | AP35: 0 | AQ35: 0 | AS35: =AO35+AP35+AR35-AQ35 -> 0.001666 | AV35: =AS35 -> 0.001666 | AX35: 0 | AZ35: =AV35+AW35+AY35-AX35 -> 0.001666 | BC35: =AZ35 -> 0.001666 | BD35: 0 | BE35: 0 | BF35: 0 | BG35: =BC35+BD35+BF35-BE35 -> 0.001666 | BH35: 5 | BJ35: =BG35 -> 0.001666 | BK35: 5 | BL35: 0 | BM35: 0 | BN35: =BJ35+BK35+BM35-BL35 -> 5.001666 | BQ35: =BN35 -> 5.001666 | BS35: 5 | BT35: 0 | BU35: =BQ35+BR35+BT35-BS35 -> 0.001666 | BX35: =BU35 -> 0.001666 | BZ35: 0 | CA35: 0 | CB35: =BX35+BY35+CA35-BZ35 -> 0.001666 | CC35: 15 | CE35: =CB35 -> 0.001666 | CF35: 15 | CG35: 10.041666 | CH35: 0 | CI35: =CE35+CF35+CH35-CG35 -> 4.96
A36: SAUCE | B36: WKFLD. PEPRICO SAUCE 90GM*36 | C36: 2628 | D36: 9370.6294 | E36: 36 | F36: 5.666666 | G36: 0 | H36: 3 | I36: 0 | J36: =F36+G36+I36-H36 -> 2.666666 | M36: =J36 -> 2.666666 | N36: 0 | O36: 2 | P36: 0 | Q36: =M36+N36+P36-O36 -> 0.666666 | T36: =Q36 -> 0.666666 | U36: 0 | V36: 0 | X36: =T36+U36+W36-V36 -> 0.666666 | AA36: =X36 -> 0.666666 | AC36: 0 | AD36: 1 | AE36: =AA36+AB36+AD36-AC36 -> 1.666666 | AH36: =AE36 -> 1.666666 | AJ36: 2 | AK36: 1 | AL36: =AH36+AI36+AK36-AJ36 -> 0.666666 | AO36: =AL36 -> 0.666666 | AP36: 5 | AQ36: 2.6667 | AS36: =AO36+AP36+AR36-AQ36 -> 2.999966 | AV36: =AS36 -> 2.999966 | AX36: 5.4444 | AY36: 3.47 | AZ36: =AV36+AW36+AY36-AX36 -> 1.025566 | BC36: =AZ36 -> 1.025566 | BD36: 0 | BE36: 0 | BF36: 0 | BG36: =BC36+BD36+BF36-BE36 -> 1.025566 | BH36: 50 | BJ36: =BG36 -> 1.025566 | BK36: 50 | BL36: 11.138888 | BM36: 0 | BN36: =BJ36+BK36+BM36-BL36 -> 39.886678 | BQ36: =BN36 -> 39.886678 | BS36: 18 | BT36: 2.083333 | BU36: =BQ36+BR36+BT36-BS36 -> 23.970011 | BX36: =BU36 -> 23.970011 | BY36: 0 | BZ36: 0 | CA36: 0 | CB36: =BX36+BY36+CA36-BZ36 -> 23.970011 | CE36: =CB36 -> 23.970011 | CF36: -7.8e-05 | CG36: 4 | CH36: 0.4723 | CI36: =CE36+CF36+CH36-CG36 -> 20.442233
B37: Mustard Powder Total | F37: =SUM(F35:F36) -> 9.458332 | G37: =SUM(G35:G36) -> 0 | H37: =SUM(H35:H36) -> 3 | I37: =SUM(I35:I36) -> 0 | J37: =SUM(J35:J36) -> 6.458332 | K37: =SUM(K35:K36) -> 0 | L37: =SUM(L35:L36) -> 0 | M37: =SUM(M35:M36) -> 6.458332 | ... CI37: =SUM(CI35:CI36) -> 25.402233
A38: PEANUT BUTTER | B38: WKFLD.PEANUT BUTTER CREAMY 24*340GM | C38: 1488 | D38: 4675.3247 | E38: 24 | F38: 127.95833 | G38: 0 | H38: 66 | I38: 12.59 | J38: =F38+G38+I38-H38 -> 74.548333 | L38: 200 | M38: =J38 -> 74.548333 | N38: 200 | O38: 79.21 | P38: 8.33 | Q38: =M38+N38+P38-O38 -> 203.66833 | S38: 100 | T38: =Q38 -> 203.66833 | U38: 100 | V38: 79.29 | X38: =T38+U38+W38-V38 -> 224.37833 | AA38: =X38 -> 224.37833 | AC38: 81 | AD38: 8.41 | AE38: =AA38+AB38+AD38-AC38 -> 151.78833 | AH38: =AE38 -> 151.78833 | AJ38: 113.21 | AK38: 6.5 | AL38: =AH38+AI38+AK38-AJ38 -> 45.078333 | AM38: 100 | AN38: 50 | AO38: =AL38 -> 45.078333 | AP38: 150 | AQ38: 111.5833 | AS38: =AO38+AP38+AR38-AQ38 -> 83.495033 | AV38: =AS38 -> 83.495033 | AX38: 24.1667 | AZ38: =AV38+AW38+AY38-AX38 -> 59.328333 | BC38: =AZ38 -> 59.328333 | BD38: 100 | BE38: 15 | BF38: 0 | BG38: =BC38+BD38+BF38-BE38 -> 144.32833 | BJ38: =BG38 -> 144.32833 | BK38: 0 | BL38: 27.041666 | BM38: 50.625 | BN38: =BJ38+BK38+BM38-BL38 -> 167.91167 | BQ38: =BN38 -> 167.91167 | BS38: 49 | BT38: 30.833333 | BU38: =BQ38+BR38+BT38-BS38 -> 149.745 | BX38: =BU38 -> 149.745 | BY38: 0 | BZ38: 25 | CA38: 9.4583 | CB38: =BX38+BY38+CA38-BZ38 -> 134.2033 | CE38: =CB38 -> 134.2033 | CF38: -3.4e-05 | CG38: =94-50+37.99 -> 81.99 | CH38: 8.5417 | CI38: =CE38+CF38+CH38-CG38 -> 60.754966
A39: PEANUT BUTTER | B39: WKFLD.PEANUT BUTTER CRUNCHY 24*340GM | C39: 1488 | D39: 4675.3247 | E39: 24 | F39: 115.33333 | G39: 0 | H39: 66 | I39: 18.88 | J39: =F39+G39+I39-H39 -> 68.213333 | L39: 200 | M39: =J39 -> 68.213333 | N39: 200 | O39: 73.29 | P39: 4 | Q39: =M39+N39+P39-O39 -> 198.92333 | S39: 100 | T39: =Q39 -> 198.92333 | U39: 100 | V39: 95.25 | X39: =T39+U39+W39-V39 -> 203.67333 | AA39: =X39 -> 203.67333 | AC39: 86.21 | AD39: 19.41 | AE39: =AA39+AB39+AD39-AC39 -> 136.87333 | AH39: =AE39 -> 136.87333 | AJ39: 97.21 | AK39: 35.67 | AL39: =AH39+AI39+AK39-AJ39 -> 75.333333 | AM39: 100 | AN39: 50 | AO39: =AL39 -> 75.333333 | AP39: 150 | AQ39: 111.1217 | AS39: =AO39+AP39+AR39-AQ39 -> 114.21163 | AV39: =AS39 -> 114.21163 | AX39: 24 | AZ39: =AV39+AW39+AY39-AX39 -> 90.211633 | BC39: =AZ39 -> 90.211633 | BD39: 100 | BE39: 16 | BF39: 0 | BG39: =BC39+BD39+BF39-BE39 -> 174.21163 | BJ39: =BG39 -> 174.21163 | BK39: 0 | BL39: 30.666666 | BM39: 35.7084 | BN39: =BJ39+BK39+BM39-BL39 -> 179.25337 | BQ39: =BN39 -> 179.25337 | BS39: 49 | BT39: 27.583333 | BU39: =BQ39+BR39+BT39-BS39 -> 157.8367 | BX39: =BU39 -> 157.8367 | BY39: 0 | BZ39: 26 | CA39: 13.0417 | CB39: =BX39+BY39+CA39-BZ39 -> 144.8784 | CE39: =CB39 -> 144.8784 | CF39: -0.0001 | CG39: =56-40+12 -> 28 | CH39: 8.5001 | CI39: =CE39+CF39+CH39-CG39 -> 125.3784
A40: PEANUT BUTTER | B40: WKFLD.PEANUT BUTTER CREAMY 24*510GM | C40: 1920 | D40: 6464.7273 | E40: 24 | L40: 50 | R40: 50 | S40: 50 | T40: =Q40 -> 0 | U40: 150 | V40: 114 | X40: =T40+U40+W40-V40 -> 36 | AA40: =X40 -> 36 | AC40: 23.04 | AD40: 0 | AE40: =AA40+AB40+AD40-AC40 -> 12.96 | AH40: =AE40 -> 12.96 | AJ40: 21.9583 | AK40: 17 | AL40: =AH40+AI40+AK40-AJ40 -> 8.0017 | AM40: 100 | AO40: =AL40 -> 8.0017 | AP40: 100 | AQ40: 46 | AS40: =AO40+AP40+AR40-AQ40 -> 62.0017 | AV40: =AS40 -> 62.0017 | AX40: 31 | AZ40: =AV40+AW40+AY40-AX40 -> 31.0017 | BC40: =AZ40 -> 31.0017 | BD40: 40 | BE40: 31 | BF40: 0 | BG40: =BC40+BD40+BF40-BE40 -> 40.0017 | BJ40: =BG40 -> 40.0017 | BK40: 50 | BL40: 20.5 | BM40: 6.875 | BN40: =BJ40+BK40+BM40-BL40 -> 76.3767 | BQ40: =BN40 -> 76.3767 | BS40: 29 | BT40: 8.583333 | BU40: =BQ40+BR40+BT40-BS40 -> 55.960033 | BX40: =BU40 -> 55.960033 | BY40: 0 | BZ40: 3 | CA40: 6.625 | CB40: =BX40+BY40+CA40-BZ40 -> 59.585033 | CE40: =CB40 -> 59.585033 | CF40: 0 | CG40: 18 | CH40: 5.25 | CI40: =CE40+CF40+CH40-CG40 -> 46.835033
A41: PEANUT BUTTER | B41: WKFLD.PEANUT BUTTER CRUNCHY 24*510GM | C41: 1920 | D41: 6464.7273 | E41: 24 | L41: 50 | R41: 50 | S41: 50 | T41: =Q41 -> 0 | U41: 150 | V41: 114 | X41: =T41+U41+W41-V41 -> 36 | AA41: =X41 -> 36 | AC41: 23 | AD41: 0 | AE41: =AA41+AB41+AD41-AC41 -> 13 | AH41: =AE41 -> 13 | AJ41: 30 | AK41: 17 | AL41: =AH41+AI41+AK41-AJ41 -> 0 | AM41: 100 | AO41: =AL41 -> 0 | AP41: 100 | AQ41: 45 | AS41: =AO41+AP41+AR41-AQ41 -> 55 | AV41: =AS41 -> 55 | AX41: 31 | AZ41: =AV41+AW41+AY41-AX41 -> 24 | BC41: =AZ41 -> 24 | BD41: 40 | BE41: 37 | BF41: 0 | BG41: =BC41+BD41+BF41-BE41 -> 27 | BJ41: =BG41 -> 27 | BK41: 100 | BL41: 29.708333 | BM41: 6.9167 | BN41: =BJ41+BK41+BM41-BL41 -> 104.20837 | BQ41: =BN41 -> 104.20837 | BS41: 28 | BT41: 11.416666 | BU41: =BQ41+BR41+BT41-BS41 -> 87.625033 | BX41: =BU41 -> 87.625033 | BY41: 0 | BZ41: 8 | CA41: 8.4167 | CB41: =BX41+BY41+CA41-BZ41 -> 88.041733 | CE41: =CB41 -> 88.041733 | CF41: -6.7e-05 | CG41: 18 | CH41: 3.8334 | CI41: =CE41+CF41+CH41-CG41 -> 73.875066
B42: Mustard Powder Total | F42: =SUM(F38:F41) -> 243.29167 | G42: =SUM(G38:G41) -> 0 | H42: =SUM(H38:H41) -> 132 | I42: =SUM(I38:I41) -> 31.47 | J42: =SUM(J38:J41) -> 142.76167 | K42: =SUM(K38:K41) -> 0 | L42: =SUM(L38:L41) -> 500 | M42: =SUM(M38:M41) -> 142.76167 | ... CI42: =SUM(CI38:CI41) -> 306.84347
...

Sheet 25-26
CM2: Primary NPR | CN2: CIF INR
F3: 45748 | M3: 45778 | S3: 45809 | Y3: 45839 | AG3: 45870 | AO3: 45901 | AX3: 45931 | BE3: 45962 | BM3: 45992 | BU3: 46023 | CD3: 46054 | CM3: =SUMPRODUCT(D5:D67,CM5:CM67)/10^5 -> 104.08465 | CN3: =SUMPRODUCT(C5:C67,CN5:CN67)/10^5 -> 25.0513
A4: Category | B4: Product Description | C4: CIF Rate | D4: NPR CASE RATE | E4: Pack Size | F4: April-25 Opening | G4: PURCHASES OF APRIL | H4: PRIMARY TILL 30-04-2025 | I4: SALES RETURN | J4: CLOSING | K4: April Transit | L4: May-025 PI Plan | M4: May-25 Opening | N4: PURCHASES OF May | O4: PRIMARY TILL 30-05-2025 | P4: SALES RETURN | Q4: CLOSING | R4: May Transit | S4: June-25 Opening | T4: PURCHASES OF June | U4: PRIMARY TILL 30-06-2025 | V4: SALES RETURN | W4: CLOSING | X4: June Transit | Y4: July-25 Opening | Z4: PURCHASES OF July | AA4: PRIMARY TILL 31-07-2025 | AB4: SALES RETURN | AC4: Net sales | AD4: CLOSING | AE4: July 25 Tgt | AF4: Shrtfall | AG4: Aug-25 Opening | AH4: PURCHASES OF Aug | AI4: PRIMARY TILL 31-08-2025 | AJ4: SALES RETURN | AK4: Net sales | AL4: CLOSING | AM4: Aug25 Tgt | AN4: Shrtfall | AO4: Sept-25 Opening | AP4: PURCHASES OF Sept | AQ4: PRIMARY TILL 31-09-2025 | AR4: SALES RETURN | AS4: Net sales | AT4: CLOSING | AU4: Transit | AV4: Sept25 Tgt | AW4: Shrtfall | AX4: Oct-25 Opening | AY4: PURCHASES OF OCT | AZ4: PRIMARY TILL 30-10-2025 | BA4: SALES RETURN | BB4: Net sales | BC4: CLOSING | BD4: Transit | BE4: NOV-25 Opening | BF4: PURCHASES OF NOV | BG4: PRIMARY TILL 30-11-2025 | BH4: SALES RETURN | BI4: Net sales | BJ4: KG Stock | BK4: CLOSING Exact | BL4: PO Dec Plan | BM4: DEC-25 Opening | BN4: PURCHASES OF DEC | BO4: PRIMARY TILL 31-12-2025 | BP4: SALES RETURN | BQ4: Net sales | BR4: KG Stock | BS4: CLOSING Exact | BT4: Transit | BU4: JAN-26 Opening | BV4: PURCHASE OF JAN | BW4: PRIMARY TILL 31-01-2026 | BX4: SALES RETURN | BY4: Net sales | BZ4: KG Stock | CA4: CLOSING Exact | CB4: Transit | CC4: PO Jan FEB | CD4: JAN-26 Opening | CE4: PURCHASE OF JAN | CF4: PRIMARY TILL 28-02-2026 | CG4: SALES RETURN | CH4: Net sales | CI4: KG Stock | CJ4: CLOSING Exact | CK4: Transit | CL4: Total | CM4: March Plan | CN4: PO of Feb + March 2026
A5: BAKING POWDER | B5: WKFLD. BAKING POWDER 100*100GM | C5: 1204 | D5: 3885.101 | E5: 100 | F5: ='24-25'!CI5 -> 66.34 | G5: 50 | H5: 44.15 | J5: =F5+G5+I5-H5 -> 72.19 | M5: =J5 -> 72.19 | N5: 50 | O5: 82.18 | P5: 2.33 | Q5: =M5+N5+P5-O5 -> 42.34 | S5: =Q5 -> 42.34 | U5: 41.98 | V5: 1.05 | W5: =S5+T5+V5-U5 -> 1.41 | X5: 100 | Y5: =W5 -> 1.41 | Z5: 100 | AA5: 100.22 | AB5: 1 | AC5: =AA5-AB5 -> 99.22 | AD5: =Y5+Z5+AB5-AA5 -> 2.19 | AE5: 100 | AF5: =+AE5-AC5 -> 0.78 | AG5: =+AD5 -> 2.19 | AH5: 275 | AI5: 54.19 | AK5: =AI5-AJ5 -> 54.19 | AL5: =AG5+AH5+AJ5-AI5 -> 223 | AO5: =+AL5 -> 223 | AP5: 0 | AQ5: 49.09 | AR5: 0 | AS5: =AQ5-AR5 -> 49.09 | AT5: =AO5+AP5+AR5-AQ5 -> 173.91 | AX5: =+AT5 -> 173.91 | AY5: 0 | AZ5: 55.49 | BA5: 0 | BB5: =AZ5-BA5 -> 55.49 | BC5: =AX5+AY5+BA5-AZ5 -> 118.42 | BE5: =+BC5 -> 118.42 | BF5: 0 | BG5: 70.54 | BH5: 0 | BI5: =+BG5-BH5 -> 70.54 | BK5: =BE5+BF5+BH5-BG5-BJ5 -> 47.88 | BL5: 100 | BM5: =+BK5+BJ5 -> 47.88 | BN5: 0 | BO5: 47.1 | BP5: 0 | BQ5: =BO5-BP5 -> 47.1 | BS5: =BM5+BN5+BP5-BO5-BR5 -> 0.78 | BU5: =BS5+BR5 -> 0.78 | BV5: 100 | BW5: 63.3 | BX5: 2 | BY5: =BW5-BX5 -> 61.3 | CA5: =BU5+BV5+BX5-BW5-BZ5 -> 39.48 | CD5: 39.48 | CE5: 100 | CF5: =_xlfn.XLOOKUP(B5,[2]Sheet1!$A$4:$A$38,[2]Sheet1!$B$4:$B$38) -> 84.25 | CG5: =_xlfn.XLOOKUP(B5,[3]Sheet1!$A$4:$A$22,[3]Sheet1!$B$4:$B$22) -> 0.76 | CH5: =CF5-CG5 -> 83.49 | CJ5: =CD5+CE5+CG5-CF5-CI5 -> 55.99 | CL5: =CK5+CJ5 -> 55.99 | CM5: 50 | CN5: 50
A6: BAKING POWDER | B6: WKFLD. BAKING POWDER 30*400GM | C6: 1178 | D6: 3118.6869 | E6: 30 | F6: ='24-25'!CI6 -> 49.8334 | G6: 600 | H6: 74.5 | J6: =F6+G6+I6-H6 -> 575.3334 | M6: =J6 -> 575.3334 | N6: 200 | O6: 202.53333 | P6: 9.4667 | Q6: =M6+N6+P6-O6 -> 582.26677 | S6: =Q6 -> 582.26677 | U6: 170.16667 | V6: 51.4333 | W6: =S6+T6+V6-U6 -> 463.5334 | X6: 350 | Y6: =W6 -> 463.5334 | AA6: 146.06667 | AB6: 10 | AC6: =AA6-AB6 -> 136.06667 | AD6: =Y6+Z6+AB6-AA6 -> 327.46674 | AE6: 300 | AF6: =+AE6-AC6 -> 163.93333 | AG6: =+AD6 -> 327.46674 | AH6: 0 | AI6: 76.466666 | AK6: =AI6-AJ6 -> 76.466666 | AL6: =AG6+AH6+AJ6-AI6 -> 251.00007 | AO6: =+AL6 -> 251.00007 | AP6: 0 | AQ6: 170.56667 | AR6: 0.5667 | AS6: =AQ6-AR6 -> 169.99997 | AT6: =AO6+AP6+AR6-AQ6 -> 81.000103 | AX6: =+AT6 -> 81.000103 | AY6: 0 | AZ6: 61 | BA6: 0 | BB6: =AZ6-BA6 -> 61 | BC6: =AX6+AY6+BA6-AZ6 -> 20.000103 | BE6: =+BC6 -> 20.000103 | BF6: 0 | BG6: 20 | BH6: 0 | BI6: =+BG6-BH6 -> 20 | BK6: =BE6+BF6+BH6-BG6-BJ6 -> 0.000103 | BL6: 0 | BM6: =+BK6+BJ6 -> 0.000103 | BN6: 0 | BO6: 0 | BP6: 0 | BQ6: =BO6-BP6 -> 0 | BS6: =BM6+BN6+BP6-BO6-BR6 -> 0.000103 | BT6: 0 | BU6: =BS6+BR6 -> 0.000103 | BV6: 0 | BW6: 0 | BX6: 1 | BY6: =BW6-BX6 -> -1 | CA6: =BU6+BV6+BX6-BW6-BZ6 -> 1.000103 | CD6: 1.000103 | CE6: 0 | CF6: 0 | CG6: =_xlfn.XLOOKUP(B6,[3]Sheet1!$A$4:$A$22,[3]Sheet1!$B$4:$B$22) -> 12.4333 | CH6: =CF6-CG6 -> -12.4333 | CJ6: =CD6+CE6+CG6-CF6-CI6 -> 13.433403 | CL6: =CK6+CJ6 -> 13.433403 | CM6: 13
A7: BAKING POWDER | B7: WKFLD. BAKING POWDER 40*400GM | C7: 1475 | D7: 4158.2492 | E7: 40 | Z7: 350 | AA7: 0.375 | AC7: =AA7-AB7 -> 0.375 | AD7: =Y7+Z7+AB7-AA7 -> 349.625 | AE7: 0 | AF7: =+AE7-AC7 -> -0.375 | AG7: =+AD7 -> 349.625 | AH7: 0 | AI7: 100 | AK7: =AI7-AJ7 -> 100 | AL7: =AG7+AH7+AJ7-AI7 -> 249.625 | AO7: =+AL7 -> 249.625 | AP7: 0 | AQ7: 0 | AR7: 0 | AS7: =AQ7-AR7 -> 0 | AT7: =AO7+AP7+AR7-AQ7 -> 249.625 | AX7: =+AT7 -> 249.625 | AY7: 400 | AZ7: 125 | BA7: 0 | BB7: =AZ7-BA7 -> 125 | BC7: =AX7+AY7+BA7-AZ7 -> 524.625 | BE7: =+BC7 -> 524.625 | BF7: 0 | BG7: 148.15 | BH7: 0 | BI7: =+BG7-BH7 -> 148.15 | BK7: =BE7+BF7+BH7-BG7-BJ7 -> 376.475 | BL7: 250 | BM7: =+BK7+BJ7 -> 376.475 | BN7: 0 | BO7: 162 | BP7: 0 | BQ7: =BO7-BP7 -> 162 | BS7: =BM7+BN7+BP7-BO7-BR7 -> 214.475 | BU7: =BS7+BR7 -> 214.475 | BV7: 250 | BW7: 182 | BX7: 0 | BY7: =BW7-BX7 -> 182 | CA7: =BU7+BV7+BX7-BW7-BZ7 -> 282.475 | CD7: 282.475 | CE7: =_xlfn.XLOOKUP(B7,[4]Sheet2!$A$5:$A$25,[4]Sheet2!$B$5:$B$25) -> 250 | CF7: =_xlfn.XLOOKUP(B7,[2]Sheet1!$A$4:$A$38,[2]Sheet1!$B$4:$B$38) -> 366.075 | CG7: 0 | CH7: =CF7-CG7 -> 366.075 | CJ7: =CD7+CE7+CG7-CF7-CI7 -> 166.4 | CL7: =CK7+CJ7 -> 166.4 | CM7: 166
A8: BAKING POWDER | B8: WKFLD. BAKING POWDER 25*1KG | C8: 1740 | D8: 4856.3763 | E8: 25 | S8: 0 | V8: 0 | W8: =S8+T8+V8-U8 -> 0 | X8: 300 | Y8: 0 | Z8: 0 | AA8: 0 | AB8: 0 | AC8: =AA8-AB8 -> 0 | AD8: =Y8+Z8+AB8-AA8 -> 0 | AE8: 0 | AF8: =+AE8-AC8 -> 0 | AG8: =+AD8 -> 0 | AH8: 300 | AI8: 55.32 | AK8: =AI8-AJ8 -> 55.32 | AL8: =AG8+AH8+AJ8-AI8 -> 244.68 | AO8: =+AL8 -> 244.68 | AP8: 150 | AQ8: 20 | AR8: 0 | AS8: =AQ8-AR8 -> 20 | AT8: =AO8+AP8+AR8-AQ8 -> 374.68 | AX8: =+AT8 -> 374.68 | AY8: 0 | AZ8: 0.12 | BA8: 0 | BB8: =AZ8-BA8 -> 0.12 | BC8: =AX8+AY8+BA8-AZ8 -> 374.56 | BE8: =+BC8 -> 374.56 | BF8: 0 | BG8: 1 | BH8: 0 | BI8: =+BG8-BH8 -> 1 | BK8: =BE8+BF8+BH8-BG8-BJ8 -> 373.56 | BL8: 0 | BM8: =+BK8+BJ8 -> 373.56 | BN8: 0 | BO8: 26 | BP8: 15 | BQ8: =BO8-BP8 -> 11 | BS8: =BM8+BN8+BP8-BO8-BR8 -> 362.56 | BT8: 0 | BU8: =BS8+BR8 -> 362.56 | BV8: 0 | BW8: 6 | BX8: 0 | BY8: =BW8-BX8 -> 6 | CA8: =BU8+BV8+BX8-BW8-BZ8 -> 356.56 | CD8: 356.56 | CE8: 0 | CF8: =_xlfn.XLOOKUP(B8,[2]Sheet1!$A$4:$A$38,[2]Sheet1!$B$4:$B$38) -> 2 | CG8: 0 | CH8: =CF8-CG8 -> 2 | CJ8: =CD8+CE8+CG8-CF8-CI8 -> 354.56 | CL8: =CK8+CJ8 -> 354.56 | CM8: 50
A9: BAKING POWDER | B9: WKFLD. BAKING POWDER 6*3KG | C9: 1248 | D9: 3358.5859 | E9: 6 | Z9: 100 | AA9: 0 | AC9: =AA9-AB9 -> 0 | AD9: =Y9+Z9+AB9-AA9 -> 100 | AE9: 0 | AF9: =+AE9-AC9 -> 0 | AG9: =+AD9 -> 100 | AH9: 70 | AI9: 60 | AK9: =AI9-AJ9 -> 60 | AL9: =AG9+AH9+AJ9-AI9 -> 110 | AO9: =+AL9 -> 110 | AP9: 300 | AQ9: 90 | AR9: 0 | AS9: =AQ9-AR9 -> 90 | AT9: =AO9+AP9+AR9-AQ9 -> 320 | AX9: =+AT9 -> 320 | AY9: 30 | AZ9: 85.333333 | BA9: 0 | BB9: =AZ9-BA9 -> 85.333333 | BC9: =AX9+AY9+BA9-AZ9 -> 264.66667 | BE9: =+BC9 -> 264.66667 | BF9: 0 | BG9: 140 | BH9: 0 | BI9: =+BG9-BH9 -> 140 | BK9: =BE9+BF9+BH9-BG9-BJ9 -> 124.66667 | BL9: 100 | BM9: =+BK9+BJ9 -> 124.66667 | BN9: 0 | BO9: 85 | BP9: 0 | BQ9: =BO9-BP9 -> 85 | BS9: =BM9+BN9+BP9-BO9-BR9 -> 39.666667 | BU9: =BS9+BR9 -> 39.666667 | BV9: 100 | BW9: 124.3333 | BX9: 0 | BY9: =BW9-BX9 -> 124.3333 | CA9: =BU9+BV9+BX9-BW9-BZ9 -> 15.333367 | CD9: 15.333367 | CE9: =_xlfn.XLOOKUP(B9,[4]Sheet2!$A$5:$A$25,[4]Sheet2!$B$5:$B$25) -> 150 | CF9: =_xlfn.XLOOKUP(B9,[2]Sheet1!$A$4:$A$38,[2]Sheet1!$B$4:$B$38) -> 150 | CG9: 0 | CH9: =CF9-CG9 -> 150 | CJ9: =CD9+CE9+CG9-CF9-CI9 -> 15.333367 | CL9: =CK9+CJ9 -> 15.333367 | CM9: 15 | CN9: 150
A10: BAKING POWDER | B10: WKFLD. BAKING POWDER 4*3KG | C10: 832 | D10: 2239.0572 | E10: 4 | F10: ='24-25'!CI7 -> 407.5 | G10: 0 | H10: 67 | J10: =F10+G10+I10-H10 -> 340.5 | M10: =J10 -> 340.5 | N10: 100 | O10: 144 | P10: 0 | Q10: =M10+N10+P10-O10 -> 296.5 | S10: =Q10 -> 296.5 | U10: 116.25 | V10: 14.25 | W10: =S10+T10+V10-U10 -> 194.5 | X10: 100 | Y10: =W10 -> 194.5 | AA10: 105 | AB10: 0 | AC10: =AA10-AB10 -> 105 | AD10: =Y10+Z10+AB10-AA10 -> 89.5 | AE10: 250 | AF10: =+AE10-AC10 -> 145 | AG10: =+AD10 -> 89.5 | AH10: 0 | AI10: 89 | AK10: =AI10-AJ10 -> 89 | AL10: =AG10+AH10+AJ10-AI10 -> 0.5 | AO10: =+AL10 -> 0.5 | AP10: 0 | AQ10: 0 | AR10: 0 | AS10: =AQ10-AR10 -> 0 | AT10: =AO10+AP10+AR10-AQ10 -> 0.5 | AX10: =+AT10 -> 0.5 | AY10: 0 | AZ10: 0 | BA10: 0 | BB10: =AZ10-BA10 -> 0 | BC10: =AX10+AY10+BA10-AZ10 -> 0.5 | BE10: =+BC10 -> 0.5 | BF10: 0 | BG10: 12 | BH10: 12 | BI10: =+BG10-BH10 -> 0 | BK10: =BE10+BF10+BH10-BG10-BJ10 -> 0.5 | BL10: 0 | BM10: =+BK10+BJ10 -> 0.5 | BN10: 0 | BO10: 0 | BP10: 0 | BQ10: =BO10-BP10 -> 0 | BS10: =BM10+BN10+BP10-BO10-BR10 -> 0.5 | BT10: 0 | BU10: =BS10+BR10 -> 0.5 | BV10: 0 | BW10: 0 | BX10: 1 | BY10: =BW10-BX10 -> -1 | CA10: =BU10+BV10+BX10-BW10-BZ10 -> 1.5 | CD10: 1.5 | CE10: 0 | CF10: 0 | CG10: =_xlfn.XLOOKUP(B10,[3]Sheet1!$A$4:$A$22,[3]Sheet1!$B$4:$B$22) -> 5 | CH10: =CF10-CG10 -> -5 | CJ10: =CD10+CE10+CG10-CF10-CI10 -> 6.5 | CL10: =CK10+CJ10 -> 6.5 | CM10: 6
B11: Baking Powder Total | F11: =SUM(F5:F10) -> 523.6734 | G11: =SUM(G5:G10) -> 650 | H11: =SUM(H5:H10) -> 185.65 | I11: =SUM(I5:I10) -> 0 | J11: =SUM(J5:J10) -> 988.0234 | K11: =SUM(K5:K10) -> 0 | L11: =SUM(L5:L10) -> 0 | M11: =SUM(M5:M10) -> 988.0234 | ... BV11: =SUM(BV5:BV10) -> 450 | BW11: 375.6333 | BX11: 4 | BY11: =SUM(BY5:BY10) -> 371.6333 | BZ11: =SUM(BZ5:BZ10) -> 0 | CA11: =SUM(CA5:CA10) -> 696.34847 | CB11: =SUM(CB5:CB10) -> 0 | CC11: =SUM(CC5:CC10) -> 0 | CD11: =SUM(CD5:CD10) -> 696.34847 | CE11: =SUM(CE5:CE10) -> 500 | CF11: =SUM(CF5:CF10) -> 602.325 | ... CL11: =SUM(CL5:CL10) -> 612.21677 | CN11: =SUM(CN5:CN10) -> 200
A12: BAKING SODA | B12: WKFLD. BAKING SODA 100*100GM | C12: 1160 | D12: 3885.0039 | E12: 100 | F12: ='24-25'!CI9 -> 64.82 | G12: 50 | H12: 42.15 | J12: =F12+G12+I12-H12 -> 72.67 | M12: =J12 -> 72.67 | N12: 50 | O12: 67.61 | P12: 0.59 | Q12: =M12+N12+P12-O12 -> 55.65 | S12: =Q12 -> 55.65 | U12: 55.83 | V12: 2.17 | W12: =S12+T12+V12-U12 -> 1.99 | X12: 70 | Y12: =W12 -> 1.99 | Z12: 70 | AA12: 72.54 | AB12: 1 | AC12: =AA12-AB12 -> 71.54 | AD12: =Y12+Z12+AB12-AA12 -> 0.45 | AE12: 100 | AF12: =+AE12-AC12 -> 28.46 | AG12: =+AD12 -> 0.45 | AH12: 100 | AI12: 79.64 | AK12: =AI12-AJ12 -> 79.64 | AL12: =AG12+AH12+AJ12-AI12 -> 20.81 | AO12: =+AL12 -> 20.81 | AP12: 100 | AQ12: 72 | AR12: 0 | AS12: =AQ12-AR12 -> 72 | AT12: =AO12+AP12+AR12-AQ12 -> 48.81 | AX12: =+AT12 -> 48.81 | AY12: 150 | AZ12: 53.07 | BA12: 0 | BB12: =AZ12-BA12 -> 53.07 | BC12: =AX12+AY12+BA12-AZ12 -> 145.74 | BE12: =+BC12 -> 145.74 | BF12: 0 | BG12: 88.85 | BH12: 2 | BI12: =+BG12-BH12 -> 86.85 | BK12: =BE12+BF12+BH12-BG12-BJ12 -> 58.89 | BL12: 100 | BM12: =+BK12+BJ12 -> 58.89 | BN12: 0 | BO12: 52.1 | BP12: 0 | BQ12: =BO12-BP12 -> 52.1 | BS12: =BM12+BN12+BP12-BO12-BR12 -> 6.79 | BU12: =BS12+BR12 -> 6.79 | BV12: 100 | BW12: 68.62 | BX12: 1 | BY12: =BW12-BX12 -> 67.62 | CA12: =BU12+BV12+BX12-BW12-BZ12 -> 39.17 | CD12: 39.17 | CE12: =_xlfn.XLOOKUP(B12,[4]Sheet2!$A$5:$A$25,[4]Sheet2!$B$5:$B$25) -> 100 | CF12: =_xlfn.XLOOKUP(B12,[2]Sheet1!$A$4:$A$38,[2]Sheet1!$B$4:$B$38) -> 61.43 | CG12: =_xlfn.XLOOKUP(B12,[3]Sheet1!$A$4:$A$22,[3]Sheet1!$B$4:$B$22) -> 1.65 | CH12: =CF12-CG12 -> 59.78 | CJ12: =CD12+CE12+CG12-CF12-CI12 -> 79.39 | CL12: =CK12+CJ12 -> 79.39 | CM12: 75 | CN12: 25
A13: BAKING SODA | B13: WKFLD. BAKING SODA 40*400GM | C13: 1413 | D13: 4158.2492 | E13: 40 | S13: 0 | V13: 0 | W13: =S13+T13+V13-U13 -> 0 | X13: 100 | Y13: 0 | Z13: 0 | AA13: 0 | AB13: 0 | AC13: =AA13-AB13 -> 0 | AD13: =Y13+Z13+AB13-AA13 -> 0 | AE13: 0 | AF13: =+AE13-AC13 -> 0 | AG13: =+AD13 -> 0 | AH13: 100 | AI13: 63.025 | AK13: =AI13-AJ13 -> 63.025 | AL13: =AG13+AH13+AJ13-AI13 -> 36.975 | AO13: =+AL13 -> 36.975 | AP13: 400 | AQ13: 17 | AR13: 0 | AS13: =AQ13-AR13 -> 17 | AT13: =AO13+AP13+AR13-AQ13 -> 419.975 | AX13: =+AT13 -> 419.975 | AY13: 0 | AZ13: 13.025 | BA13: 0 | BB13: =AZ13-BA13 -> 13.025 | BC13: =AX13+AY13+BA13-AZ13 -> 406.95 | BE13: =+BC13 -> 406.95 | BF13: 0 | BG13: 24.05 | BH13: 0 | BI13: =+BG13-BH13 -> 24.05 | BK13: =BE13+BF13+BH13-BG13-BJ13 -> 382.9 | BL13: 0 | BM13: =+BK13+BJ13 -> 382.9 | BN13: 0 | BO13: 52 | BP13: 0 | BQ13: =BO13-BP13 -> 52 | BS13: =BM13+BN13+BP13-BO13-BR13 -> 330.9 | BT13: 0 | BU13: =BS13+BR13 -> 330.9 | BV13: 0 | BW13: 24 | BX13: 0 | BY13: =BW13-BX13 -> 24 | CA13: =BU13+BV13+BX13-BW13-BZ13 -> 306.9 | CD13: 306.9 | CE13: 0 | CF13: =_xlfn.XLOOKUP(B13,[2]Sheet1!$A$4:$A$38,[2]Sheet1!$B$4:$B$38) -> 40 | CG13: 0 | CH13: =CF13-CG13 -> 40 | CJ13: =CD13+CE13+CG13-CF13-CI13 -> 266.9 | CL13: =CK13+CJ13 -> 266.9 | CM13: 266
B14: Baking Soda Total | F14: =SUM(F12) -> 64.82 | G14: =SUM(G12) -> 50 | H14: =SUM(H12) -> 42.15 | I14: =SUM(I12) -> 0 | J14: =SUM(J12) -> 72.67 | K14: =SUM(K12) -> 0 | L14: =SUM(L12) -> 0 | M14: =SUM(M12) -> 72.67 | ... U14: =SUM(U12) -> 55.83 | V14: =SUM(V12:V13) -> 2.17 | W14: =SUM(W12:W13) -> 1.99 | X14: =SUM(X12:X13) -> 170 | Y14: =SUM(Y12:Y13) -> 1.99 | Z14: =SUM(Z12:Z13) -> 70 | AA14: =SUM(AA12:AA13) -> 72.54 | AB14: =SUM(AB12:AB13) -> 1 | AC14: =SUM(AC12:AC13) -> 71.54 | ... BV14: =SUM(BV12:BV13) -> 100 | BW14: 92.62 | BX14: 1 | BY14: =SUM(BY12:BY13) -> 91.62 | BZ14: =SUM(BZ12:BZ13) -> 0 | CA14: =SUM(CA12:CA13) -> 346.07 | CB14: =SUM(CB12:CB13) -> 0 | CC14: =SUM(CC12:CC13) -> 0 | CD14: =SUM(CD12:CD13) -> 346.07 | CE14: =SUM(CE12:CE13) -> 100 | CF14: =SUM(CF12:CF13) -> 101.43 | ... CL14: =SUM(CL12:CL13) -> 346.29 | CN14: =SUM(CN12:CN13) -> 25
A15: COCOA POWDER | B15: WKFLD. COCOA POWDER 40*150GM | C15: 5700 | D15: 18648.019 | E15: 40 | F15: ='24-25'!CI11 -> 20.4 | G15: 20 | H15: 25 | J15: =F15+G15+I15-H15 -> 15.4 | M15: =J15 -> 15.4 | N15: 25 | O15: =38.925-15-10 -> 13.925 | P15: 1.925 | Q15: =M15+N15+P15-O15 -> 28.4 | S15: =Q15 -> 28.4 | U15: 32.225 | V15: 33.9 | W15: =S15+T15+V15-U15 -> 30.075 | X15: 50 | Y15: =W15 -> 30.075 | Z15: 50 | AA15: =28-10 -> 18 | AB15: 1 | AC15: =AA15-AB15 -> 17 | AD15: =Y15+Z15+AB15-AA15 -> 63.075 | AE15: 10 | AF15: =+AE15-AC15 -> -7 | AG15: =+AD15 -> 63.075 | AH15: 0 | AI15: 25 | AK15: =AI15-AJ15 -> 25 | AL15: =AG15+AH15+AJ15-AI15 -> 38.075 | AO15: =+AL15 -> 38.075 | AP15: 0 | AQ15: 1.25 | AR15: 0.475 | AS15: =AQ15-AR15 -> 0.775 | AT15: =AO15+AP15+AR15-AQ15 -> 37.3 | AX15: =+AT15 -> 37.3 | AY15: 25 | AZ15: 29.025 | BA15: 0 | BB15: =AZ15-BA15 -> 29.025 | BC15: =AX15+AY15+BA15-AZ15 -> 33.275 | BE15: =+BC15 -> 33.275 | BF15: 0 | BG15: 4.975 | BH15: 2 | BI15: =+BG15-BH15 -> 2.975 | BJ15: 29.3 | BK15: =BE15+BF15+BH15-BG15-BJ15 -> 1 | BL15: 50 | BM15: =+BK15+BJ15 -> 30.3 | BN15: 0 | BO15: 35.475 | BP15: 9.475 | BQ15: =BO15-BP15 -> 26 | BR15: 4.3 | BS15: =BM15+BN15+BP15-BO15-BR15 -> -9.7699626e-15 | BU15: =BS15+BR15 -> 4.3 | BV15: 50 | BW15: 50 | BX15: 2 | BY15: =BW15-BX15 -> 48 | BZ15: 4.3 | CA15: =BU15+BV15+BX15-BW15-BZ15 -> 2 | CD15: 2 | CE15: =_xlfn.XLOOKUP(B15,[4]Sheet2!$A$5:$A$25,[4]Sheet2!$B$5:$B$25) -> 50 | CF15: =_xlfn.XLOOKUP(B15,[2]Sheet1!$A$4:$A$38,[2]Sheet1!$B$4:$B$38) -> 26 | CG15: =_xlfn.XLOOKUP(B15,[3]Sheet1!$A$4:$A$22,[3]Sheet1!$B$4:$B$22) -> 0.625 | CH15: =CF15-CG15 -> 25.375 | CI15: 4.3 | CJ15: =CD15+CE15+CG15-CF15-CI15 -> 22.325 | CL15: =CK15+CJ15 -> 22.325 | CM15: 20 | CN15: 50
A16: COCOA POWDER | B16: WKFLD. COCOA POWDER 96*50GM | C16: 4800 | D16: 22377.622 | E16: 96 | F16: ='24-25'!CI12 -> 38.885416 | G16: 0 | H16: 19 | J16: =F16+G16+I16-H16 -> 19.885416 | M16: =J16 -> 19.885416 | N16: 25 | O16: =33.895833-15-10 -> 8.895833 | P16: 0.8958 | Q16: =M16+N16+P16-O16 -> 36.885383 | S16: =Q16 -> 36.885383 | U16: 26.322933 | V16: 17.2813 | W16: =S16+T16+V16-U16 -> 27.84375 | X16: 50 | Y16: =W16 -> 27.84375 | Z16: 50 | AA16: =22-10 -> 12 | AB16: 1 | AC16: =AA16-AB16 -> 11 | AD16: =Y16+Z16+AB16-AA16 -> 66.84375 | AE16: 10 | AF16: =+AE16-AC16 -> -1 | AG16: =+AD16 -> 66.84375 | AH16: 0 | AI16: 25 | AK16: =AI16-AJ16 -> 25 | AL16: =AG16+AH16+AJ16-AI16 -> 41.84375 | AO16: =+AL16 -> 41.84375 | AP16: 0 | AQ16: 6 | AR16: 0 | AS16: =AQ16-AR16 -> 6 | AT16: =AO16+AP16+AR16-AQ16 -> 35.84375 | AX16: =+AT16 -> 35.84375 | AY16: 0 | AZ16: 12 | BA16: 0 | BB16: =AZ16-BA16 -> 12 | BC16: =AX16+AY16+BA16-AZ16 -> 23.84375 | BE16: =+BC16 -> 23.84375 | BF16: 0 | BG16: 9 | BH16: 2 | BI16: =+BG16-BH16 -> 7 | BJ16: 16.77 | BK16: =BE16+BF16+BH16-BG16-BJ16 -> 0.07375 | BL16: 40 | BM16: =+BK16+BJ16 -> 16.84375 | BN16: 0 | BO16: 0.072916 | BP16: 0 | BQ16: =BO16-BP16 -> 0.072916 | BR16: 16.77 | BS16: =BM16+BN16+BP16-BO16-BR16 -> 0.000834 | BU16: =BS16+BR16 -> 16.770834 | BV16: 40 | BW16: 15 | BX16: 0.6563 | BY16: =BW16-BX16 -> 14.3437 | BZ16: 16.77 | CA16: =BU16+BV16+BX16-BW16-BZ16 -> 25.657134 | CD16: 25.657134 | CE16: =_xlfn.XLOOKUP(B16,[4]Sheet2!$A$5:$A$25,[4]Sheet2!$B$5:$B$25) -> 40 | CF16: =_xlfn.XLOOKUP(B16,[2]Sheet1!$A$4:$A$38,[2]Sheet1!$B$4:$B$38) -> 17 | CG16: =_xlfn.XLOOKUP(B16,[3]Sheet1!$A$4:$A$22,[3]Sheet1!$B$4:$B$22) -> 0.8021 | CH16: =CF16-CG16 -> 16.1979 | CI16: 16.77 | CJ16: =CD16+CE16+CG16-CF16-CI16 -> 32.689234 | CL16: =CK16+CJ16 -> 32.689234 | CM16: 20 | CN16: 25
B17: Cocoa Powder Total | F17: =SUM(F15:F16) -> 59.285416 | G17: =SUM(G15:G16) -> 20 | H17: =SUM(H15:H16) -> 44 | I17: =SUM(I15:I16) -> 0 | J17: =SUM(J15:J16) -> 35.285416 | K17: =SUM(K15:K16) -> 0 | L17: =SUM(L15:L16) -> 0 | M17: =SUM(M15:M16) -> 35.285416 | ... BV17: =SUM(BV15:BV16) -> 90 | BW17: 65 | BX17: 2.6563 | BY17: =SUM(BY15:BY16) -> 62.3437 | BZ17: =SUM(BZ15:BZ16) -> 21.07 | CA17: =SUM(CA15:CA16) -> 27.657134 | CB17: =SUM(CB15:CB16) -> 0 | CC17: =SUM(CC15:CC16) -> 0 | CD17: =SUM(CD15:CD16) -> 27.657134 | CE17: =SUM(CE15:CE16) -> 90 | CF17: =SUM(CF15:CF16) -> 43 | ... CL17: =SUM(CL15:CL16) -> 55.014234 | CN17: =SUM(CN15:CN16) -> 75
A18: CORNFLOUR | B18: WKFLD. CORNFLOUR 100*100GM | C18: 950 | D18: 3885.0039 | E18: 100 | F18: ='24-25'!CI14 -> 72.32 | G18: 0 | H18: 43 | J18: =F18+G18+I18-H18 -> 29.32 | M18: =J18 -> 29.32 | N18: 70 | O18: 43.46 | P18: 2.46 | Q18: =M18+N18+P18-O18 -> 58.32 | S18: =Q18 -> 58.32 | U18: 28.4 | V18: 1.4 | W18: =S18+T18+V18-U18 -> 31.32 | X18: 75 | Y18: =W18 -> 31.32 | Z18: 75 | AA18: 45.05 | AB18: 1 | AC18: =AA18-AB18 -> 44.05 | AD18: =Y18+Z18+AB18-AA18 -> 62.27 | AE18: 70 | AF18: =+AE18-AC18 -> 25.95 | AG18: =+AD18 -> 62.27 | AH18: 75 | AI18: 36.01 | AK18: =AI18-AJ18 -> 36.01 | AL18: =AG18+AH18+AJ18-AI18 -> 101.26 | AO18: =+AL18 -> 101.26 | AP18: 100 | AQ18: 49.21 | AR18: 0.21 | AS18: =AQ18-AR18 -> 49 | AT18: =AO18+AP18+AR18-AQ18 -> 152.26 | AX18: =+AT18 -> 152.26 | AY18: 0 | AZ18: 32 | BA18: 0 | BB18: =AZ18-BA18 -> 32 | BC18: =AX18+AY18+BA18-AZ18 -> 120.26 | BE18: =+BC18 -> 120.26 | BF18: 0 | BG18: 48 | BH18: 0 | BI18: =+BG18-BH18 -> 48 | BK18: =BE18+BF18+BH18-BG18-BJ18 -> 72.26 | BL18: 50 | BM18: =+BK18+BJ18 -> 72.26 | BN18: 0 | BO18: 40 | BP18: 0 | BQ18: =BO18-BP18 -> 40 | BS18: =BM18+BN18+BP18-BO18-BR18 -> 32.26 | BU18: =BS18+BR18 -> 32.26 | BV18: 50 | BW18: 46 | BX18: 7 | BY18: =BW18-BX18 -> 39 | CA18: =BU18+BV18+BX18-BW18-BZ18 -> 43.26 | CD18: 43.26 | CE18: =_xlfn.XLOOKUP(B18,[4]Sheet2!$A$5:$A$25,[4]Sheet2!$B$5:$B$25) -> 75 | CF18: =_xlfn.XLOOKUP(B18,[2]Sheet1!$A$4:$A$38,[2]Sheet1!$B$4:$B$38) -> 61 | CG18: =_xlfn.XLOOKUP(B18,[3]Sheet1!$A$4:$A$22,[3]Sheet1!$B$4:$B$22) -> 1.86 | CH18: =CF18-CG18 -> 59.14 | CJ18: =CD18+CE18+CG18-CF18-CI18 -> 59.12 | CL18: =CK18+CJ18 -> 59.12 | CM18: 59 | CN18: 50
A19: CORNFLOUR | B19: WKFLD. CORNFLOUR 20*500GM | C19: 790 | D19: 2079.1246 | E19: 20 | F19: ='24-25'!CI15 -> 0.65 | G19: 200 | H19: 110.65 | J19: =F19+G19+I19-H19 -> 90 | M19: =J19 -> 90 | N19: 350 | O19: 159.5 | P19: 8.5 | Q19: =M19+N19+P19-O19 -> 289 | S19: =Q19 -> 289 | U19: 77.05 | V19: 8.3 | W19: =S19+T19+V19-U19 -> 220.25 | Y19: =W19 -> 220.25 | Z19: 0 | AA19: 46.45 | AB19: 3 | AC19: =AA19-AB19 -> 43.45 | AD19: =Y19+Z19+AB19-AA19 -> 176.8 | AE19: 100 | AF19: =+AE19-AC19 -> 56.55 | AG19: =+AD19 -> 176.8 | AH19: 0 | AI19: 53.5 | AK19: =AI19-AJ19 -> 53.5 | AL19: =AG19+AH19+AJ19-AI19 -> 123.3 | AO19: =+AL19 -> 123.3 | AP19: 0 | AQ19: 33.65 | AR19: 0.65 | AS19: =AQ19-AR19 -> 33 | AT19: =AO19+AP19+AR19-AQ19 -> 90.3 | AX19: =+AT19 -> 90.3 | AY19: 0 | AZ19: 64 | BA19: 0 | BB19: =AZ19-BA19 -> 64 | BC19: =AX19+AY19+BA19-AZ19 -> 26.3 | BE19: =+BC19 -> 26.3 | BF19: 0 | BG19: 25 | BH19: 0 | BI19: =+BG19-BH19 -> 25 | BK19: =BE19+BF19+BH19-BG19-BJ19 -> 1.3 | BL19: 0 | BM19: =+BK19+BJ19 -> 1.3 | BN19: 0 | BO19: 0 | BP19: 0 | BQ19: =BO19-BP19 -> 0 | BS19: =BM19+BN19+BP19-BO19-BR19 -> 1.3 | BT19: 0 | BU19: =BS19+BR19 -> 1.3 | BV19: 0 | BW19: 14 | BX19: 21.55 | BY19: =BW19-BX19 -> -7.55 | CA19: =BU19+BV19+BX19-BW19-BZ19 -> 8.85 | CD19: 8.85 | CE19: 0 | CF19: 0 | CG19: =_xlfn.XLOOKUP(B19,[3]Sheet1!$A$4:$A$22,[3]Sheet1!$B$4:$B$22) -> 4.85 | CH19: =CF19-CG19 -> -4.85 | CJ19: =CD19+CE19+CG19-CF19-CI19 -> 13.7 | CL19: =CK19+CJ19 -> 13.7 | CM19: 13
A20: CORNFLOUR | B20: WKFLD. CORNFLOUR 30*500GM | C20: 1872 | D20: 5637.63 | E20: 30 | AG20: =+AD20 -> 0 | AH20: 0 | AI20: 0 | AK20: =AI20-AJ20 -> 0 | AL20: =AG20+AH20+AJ20-AI20 -> 0 | AO20: =+AL20 -> 0 | AP20: 150 | AQ20: 0 | AR20: 0 | AS20: =AQ20-AR20 -> 0 | AT20: =AO20+AP20+AR20-AQ20 -> 150 | AX20: =+AT20 -> 150 | AY20: 0 | AZ20: 58.133333 | BA20: 0 | BB20: =AZ20-BA20 -> 58.133333 | BC20: =AX20+AY20+BA20-AZ20 -> 91.866667 | BE20: =+BC20 -> 91.866667 | BF20: 0 | BG20: 91 | BH20: 0 | BI20: =+BG20-BH20 -> 91 | BK20: =BE20+BF20+BH20-BG20-BJ20 -> 0.866667 | BL20: 150 | BM20: =+BK20+BJ20 -> 0.866667 | BN20: 0 | BO20: 0 | BP20: 0 | BQ20: =BO20-BP20 -> 0 | BS20: =BM20+BN20+BP20-BO20-BR20 -> 0.866667 | BU20: =BS20+BR20 -> 0.866667 | BV20: 200 | BW20: 85.3334 | BX20: 0 | BY20: =BW20-BX20 -> 85.3334 | CA20: =BU20+BV20+BX20-BW20-BZ20 -> 115.53327 | CD20: 115.53327 | CE20: =_xlfn.XLOOKUP(B20,[4]Sheet2!$A$5:$A$25,[4]Sheet2!$B$5:$B$25) -> 100 | CF20: =_xlfn.XLOOKUP(B20,[2]Sheet1!$A$4:$A$38,[2]Sheet1!$B$4:$B$38) -> 108.2333 | CG20: 0 | CH20: =CF20-CG20 -> 108.2333 | CJ20: =CD20+CE20+CG20-CF20-CI20 -> 107.29997 | CL20: =CK20+CJ20 -> 107.29997 | CM20: 55
